Workbook

Sheet MOBILE_VIEW
A1: MOBILE_VIEW - Xem nhanh trên điện thoại (không nhập dữ liệu)
A3: Chọn ngày: | B3: 46071
A4: Chọn thợ: | B4: tony
A5: Chọn tuần (WeekStart Mon): | B5: 46082
A6: Chọn tháng (yyyy-mm): | B6: =TEXT(TODAY(),"yyyy-mm") -> 2026-03
A8: TỔNG NGÀY (theo thợ) | H8: TỔNG TUẦN (Selected Tech theo ngày)
A9: Tech | B9: # Khách | C9: Service | D9: Tech Share | E9: Tip | F9: Salon Net | H9: Date | I9: # | J9: Service | K9: Tip | L9: Tech Share | M9: Salon Net
A10: KEN | B10: =COUNTIFS(INPUT!J:J,$A10, INPUT!L:L, INT($B$3)) -> 0 | C10: =SUMIFS(INPUT!C:C, INPUT!J:J,$A10, INPUT!L:L, INT($B$3)) -> 0 | D10: =SUMIFS(INPUT!E:E, INPUT!J:J,$A10, INPUT!L:L, INT($B$3)) -> 0 | E10: =SUMIFS(INPUT!D:D, INPUT!J:J,$A10, INPUT!L:L, INT($B$3)) -> 0 | F10: =SUMIFS(INPUT!G:G, INPUT!J:J,$A10, INPUT!L:L, INT($B$3)) -> 0 | H10: =IF($B$5="","", $B$5+0) -> 46082 | I10: =IF($B$5="","",IF($B$4="ALL",COUNTIFS(INPUT!K:K,$B$5,INPUT!L:L,H10),COUNTIFS(INPUT!J:J,$B$4,INPUT!K:K,$B$5,INPUT!L:L,H10))) -> 0 | J10: =IF($B$5="","",IF($B$4="ALL",SUMIFS(INPUT!C:C,INPUT!K:K,$B$5,INPUT!L:L,H10),SUMIFS(INPUT!C:C,INPUT!J:J,$B$4,INPUT!K:K,$B$5,INPUT!L:L,H10))) -> 0 | K10: =IF($B$5="","",IF($B$4="ALL",SUMIFS(INPUT!D:D,INPUT!K:K,$B$5,INPUT!L:L,H10),SUMIFS(INPUT!D:D,INPUT!J:J,$B$4,INPUT!K:K,$B$5,INPUT!L:L,H10))) -> 0 | L10: =IF($B$5="","",IF($B$4="ALL",SUMIFS(INPUT!E:E,INPUT!K:K,$B$5,INPUT!L:L,H10),SUMIFS(INPUT!E:E,INPUT!J:J,$B$4,INPUT!K:K,$B$5,INPUT!L:L,H10))) -> 0 | M10: =IF($B$5="","",IF($B$4="ALL",SUMIFS(INPUT!G:G,INPUT!K:K,$B$5,INPUT!L:L,H10),SUMIFS(INPUT!G:G,INPUT!J:J,$B$4,INPUT!K:K,$B$5,INPUT!L:L,H10))) -> 0
A11: RYAN | B11: =COUNTIFS(INPUT!J:J,$A11, INPUT!L:L, INT($B$3)) -> 6 | C11: =SUMIFS(INPUT!C:C, INPUT!J:J,$A11, INPUT!L:L, INT($B$3)) -> 388 | D11: =SUMIFS(INPUT!E:E, INPUT!J:J,$A11, INPUT!L:L, INT($B$3)) -> 232.8 | E11: =SUMIFS(INPUT!D:D, INPUT!J:J,$A11, INPUT!L:L, INT($B$3)) -> 0 | F11: =SUMIFS(INPUT!G:G, INPUT!J:J,$A11, INPUT!L:L, INT($B$3)) -> 155.2 | H11: =IF($B$5="","", $B$5+1) -> 46083 | I11: =IF($B$5="","",IF($B$4="ALL",COUNTIFS(INPUT!K:K,$B$5,INPUT!L:L,H11),COUNTIFS(INPUT!J:J,$B$4,INPUT!K:K,$B$5,INPUT!L:L,H11))) -> 0 | J11: =IF($B$5="","",IF($B$4="ALL",SUMIFS(INPUT!C:C,INPUT!K:K,$B$5,INPUT!L:L,H11),SUMIFS(INPUT!C:C,INPUT!J:J,$B$4,INPUT!K:K,$B$5,INPUT!L:L,H11))) -> 0 | K11: =IF($B$5="","",IF($B$4="ALL",SUMIFS(INPUT!D:D,INPUT!K:K,$B$5,INPUT!L:L,H11),SUMIFS(INPUT!D:D,INPUT!J:J,$B$4,INPUT!K:K,$B$5,INPUT!L:L,H11))) -> 0 | L11: =IF($B$5="","",IF($B$4="ALL",SUMIFS(INPUT!E:E,INPUT!K:K,$B$5,INPUT!L:L,H11),SUMIFS(INPUT!E:E,INPUT!J:J,$B$4,INPUT!K:K,$B$5,INPUT!L:L,H11))) -> 0 | M11: =IF($B$5="","",IF($B$4="ALL",SUMIFS(INPUT!G:G,INPUT!K:K,$B$5,INPUT!L:L,H11),SUMIFS(INPUT!G:G,INPUT!J:J,$B$4,INPUT!K:K,$B$5,INPUT!L:L,H11))) -> 0
A12: CRIS | B12: =COUNTIFS(INPUT!J:J,$A12, INPUT!L:L, INT($B$3)) -> 7 | C12: =SUMIFS(INPUT!C:C, INPUT!J:J,$A12, INPUT!L:L, INT($B$3)) -> 375 | D12: =SUMIFS(INPUT!E:E, INPUT!J:J,$A12, INPUT!L:L, INT($B$3)) -> 187.5 | E12: =SUMIFS(INPUT!D:D, INPUT!J:J,$A12, INPUT!L:L, INT($B$3)) -> 0 | F12: =SUMIFS(INPUT!G:G, INPUT!J:J,$A12, INPUT!L:L, INT($B$3)) -> 187.5 | H12: =IF($B$5="","", $B$5+2) -> 46084 | I12: =IF($B$5="","",IF($B$4="ALL",COUNTIFS(INPUT!K:K,$B$5,INPUT!L:L,H12),COUNTIFS(INPUT!J:J,$B$4,INPUT!K:K,$B$5,INPUT!L:L,H12))) -> 0 | J12: =IF($B$5="","",IF($B$4="ALL",SUMIFS(INPUT!C:C,INPUT!K:K,$B$5,INPUT!L:L,H12),SUMIFS(INPUT!C:C,INPUT!J:J,$B$4,INPUT!K:K,$B$5,INPUT!L:L,H12))) -> 0 | K12: =IF($B$5="","",IF($B$4="ALL",SUMIFS(INPUT!D:D,INPUT!K:K,$B$5,INPUT!L:L,H12),SUMIFS(INPUT!D:D,INPUT!J:J,$B$4,INPUT!K:K,$B$5,INPUT!L:L,H12))) -> 0 | L12: =IF($B$5="","",IF($B$4="ALL",SUMIFS(INPUT!E:E,INPUT!K:K,$B$5,INPUT!L:L,H12),SUMIFS(INPUT!E:E,INPUT!J:J,$B$4,INPUT!K:K,$B$5,INPUT!L:L,H12))) -> 0 | M12: =IF($B$5="","",IF($B$4="ALL",SUMIFS(INPUT!G:G,INPUT!K:K,$B$5,INPUT!L:L,H12),SUMIFS(INPUT!G:G,INPUT!J:J,$B$4,INPUT!K:K,$B$5,INPUT!L:L,H12))) -> 0
A13: HANNI | B13: =COUNTIFS(INPUT!J:J,$A13, INPUT!L:L, INT($B$3)) -> 3 | C13: =SUMIFS(INPUT!C:C, INPUT!J:J,$A13, INPUT!L:L, INT($B$3)) -> 217 | D13: =SUMIFS(INPUT!E:E, INPUT!J:J,$A13, INPUT!L:L, INT($B$3)) -> 0 | E13: =SUMIFS(INPUT!D:D, INPUT!J:J,$A13, INPUT!L:L, INT($B$3)) -> 0 | F13: =SUMIFS(INPUT!G:G, INPUT!J:J,$A13, INPUT!L:L, INT($B$3)) -> 217 | H13: =IF($B$5="","", $B$5+3) -> 46085 | I13: =IF($B$5="","",IF($B$4="ALL",COUNTIFS(INPUT!K:K,$B$5,INPUT!L:L,H13),COUNTIFS(INPUT!J:J,$B$4,INPUT!K:K,$B$5,INPUT!L:L,H13))) -> 0 | J13: =IF($B$5="","",IF($B$4="ALL",SUMIFS(INPUT!C:C,INPUT!K:K,$B$5,INPUT!L:L,H13),SUMIFS(INPUT!C:C,INPUT!J:J,$B$4,INPUT!K:K,$B$5,INPUT!L:L,H13))) -> 0 | K13: =IF($B$5="","",IF($B$4="ALL",SUMIFS(INPUT!D:D,INPUT!K:K,$B$5,INPUT!L:L,H13),SUMIFS(INPUT!D:D,INPUT!J:J,$B$4,INPUT!K:K,$B$5,INPUT!L:L,H13))) -> 0 | L13: =IF($B$5="","",IF($B$4="ALL",SUMIFS(INPUT!E:E,INPUT!K:K,$B$5,INPUT!L:L,H13),SUMIFS(INPUT!E:E,INPUT!J:J,$B$4,INPUT!K:K,$B$5,INPUT!L:L,H13))) -> 0 | M13: =IF($B$5="","",IF($B$4="ALL",SUMIFS(INPUT!G:G,INPUT!K:K,$B$5,INPUT!L:L,H13),SUMIFS(INPUT!G:G,INPUT!J:J,$B$4,INPUT!K:K,$B$5,INPUT!L:L,H13))) -> 0
A14: AMY | B14: =COUNTIFS(INPUT!J:J,$A14, INPUT!L:L, INT($B$3)) -> 7 | C14: =SUMIFS(INPUT!C:C, INPUT!J:J,$A14, INPUT!L:L, INT($B$3)) -> 466 | D14: =SUMIFS(INPUT!E:E, INPUT!J:J,$A14, INPUT!L:L, INT($B$3)) -> 279.6 | E14: =SUMIFS(INPUT!D:D, INPUT!J:J,$A14, INPUT!L:L, INT($B$3)) -> 0 | F14: =SUMIFS(INPUT!G:G, INPUT!J:J,$A14, INPUT!L:L, INT($B$3)) -> 186.4 | H14: =IF($B$5="","", $B$5+4) -> 46086 | I14: =IF($B$5="","",IF($B$4="ALL",COUNTIFS(INPUT!K:K,$B$5,INPUT!L:L,H14),COUNTIFS(INPUT!J:J,$B$4,INPUT!K:K,$B$5,INPUT!L:L,H14))) -> 0 | J14: =IF($B$5="","",IF($B$4="ALL",SUMIFS(INPUT!C:C,INPUT!K:K,$B$5,INPUT!L:L,H14),SUMIFS(INPUT!C:C,INPUT!J:J,$B$4,INPUT!K:K,$B$5,INPUT!L:L,H14))) -> 0 | K14: =IF($B$5="","",IF($B$4="ALL",SUMIFS(INPUT!D:D,INPUT!K:K,$B$5,INPUT!L:L,H14),SUMIFS(INPUT!D:D,INPUT!J:J,$B$4,INPUT!K:K,$B$5,INPUT!L:L,H14))) -> 0 | L14: =IF($B$5="","",IF($B$4="ALL",SUMIFS(INPUT!E:E,INPUT!K:K,$B$5,INPUT!L:L,H14),SUMIFS(INPUT!E:E,INPUT!J:J,$B$4,INPUT!K:K,$B$5,INPUT!L:L,H14))) -> 0 | M14: =IF($B$5="","",IF($B$4="ALL",SUMIFS(INPUT!G:G,INPUT!K:K,$B$5,INPUT!L:L,H14),SUMIFS(INPUT!G:G,INPUT!J:J,$B$4,INPUT!K:K,$B$5,INPUT!L:L,H14))) -> 0
A15: TONY | B15: =COUNTIFS(INPUT!J:J,$A15, INPUT!L:L, INT($B$3)) -> 7 | C15: =SUMIFS(INPUT!C:C, INPUT!J:J,$A15, INPUT!L:L, INT($B$3)) -> 377 | D15: =SUMIFS(INPUT!E:E, INPUT!J:J,$A15, INPUT!L:L, INT($B$3)) -> 226.2 | E15: =SUMIFS(INPUT!D:D, INPUT!J:J,$A15, INPUT!L:L, INT($B$3)) -> 0 | F15: =SUMIFS(INPUT!G:G, INPUT!J:J,$A15, INPUT!L:L, INT($B$3)) -> 150.8 | H15: =IF($B$5="","", $B$5+5) -> 46087 | I15: =IF($B$5="","",IF($B$4="ALL",COUNTIFS(INPUT!K:K,$B$5,INPUT!L:L,H15),COUNTIFS(INPUT!J:J,$B$4,INPUT!K:K,$B$5,INPUT!L:L,H15))) -> 0 | J15: =IF($B$5="","",IF($B$4="ALL",SUMIFS(INPUT!C:C,INPUT!K:K,$B$5,INPUT!L:L,H15),SUMIFS(INPUT!C:C,INPUT!J:J,$B$4,INPUT!K:K,$B$5,INPUT!L:L,H15))) -> 0 | K15: =IF($B$5="","",IF($B$4="ALL",SUMIFS(INPUT!D:D,INPUT!K:K,$B$5,INPUT!L:L,H15),SUMIFS(INPUT!D:D,INPUT!J:J,$B$4,INPUT!K:K,$B$5,INPUT!L:L,H15))) -> 0 | L15: =IF($B$5="","",IF($B$4="ALL",SUMIFS(INPUT!E:E,INPUT!K:K,$B$5,INPUT!L:L,H15),SUMIFS(INPUT!E:E,INPUT!J:J,$B$4,INPUT!K:K,$B$5,INPUT!L:L,H15))) -> 0 | M15: =IF($B$5="","",IF($B$4="ALL",SUMIFS(INPUT!G:G,INPUT!K:K,$B$5,INPUT!L:L,H15),SUMIFS(INPUT!G:G,INPUT!J:J,$B$4,INPUT!K:K,$B$5,INPUT!L:L,H15))) -> 0
A16: STEVEN | B16: =COUNTIFS(INPUT!J:J,$A16, INPUT!L:L, INT($B$3)) -> 0 | C16: =SUMIFS(INPUT!C:C, INPUT!J:J,$A16, INPUT!L:L, INT($B$3)) -> 0 | D16: =SUMIFS(INPUT!E:E, INPUT!J:J,$A16, INPUT!L:L, INT($B$3)) -> 0 | E16: =SUMIFS(INPUT!D:D, INPUT!J:J,$A16, INPUT!L:L, INT($B$3)) -> 0 | F16: =SUMIFS(INPUT!G:G, INPUT!J:J,$A16, INPUT!L:L, INT($B$3)) -> 0 | H16: =IF($B$5="","", $B$5+6) -> 46088 | I16: =IF($B$5="","",IF($B$4="ALL",COUNTIFS(INPUT!K:K,$B$5,INPUT!L:L,H16),COUNTIFS(INPUT!J:J,$B$4,INPUT!K:K,$B$5,INPUT!L:L,H16))) -> 0 | J16: =IF($B$5="","",IF($B$4="ALL",SUMIFS(INPUT!C:C,INPUT!K:K,$B$5,INPUT!L:L,H16),SUMIFS(INPUT!C:C,INPUT!J:J,$B$4,INPUT!K:K,$B$5,INPUT!L:L,H16))) -> 0 | K16: =IF($B$5="","",IF($B$4="ALL",SUMIFS(INPUT!D:D,INPUT!K:K,$B$5,INPUT!L:L,H16),SUMIFS(INPUT!D:D,INPUT!J:J,$B$4,INPUT!K:K,$B$5,INPUT!L:L,H16))) -> 0 | L16: =IF($B$5="","",IF($B$4="ALL",SUMIFS(INPUT!E:E,INPUT!K:K,$B$5,INPUT!L:L,H16),SUMIFS(INPUT!E:E,INPUT!J:J,$B$4,INPUT!K:K,$B$5,INPUT!L:L,H16))) -> 0 | M16: =IF($B$5="","",IF($B$4="ALL",SUMIFS(INPUT!G:G,INPUT!K:K,$B$5,INPUT!L:L,H16),SUMIFS(INPUT!G:G,INPUT!J:J,$B$4,INPUT!K:K,$B$5,INPUT!L:L,H16))) -> 0
A17: BEN | B17: =COUNTIFS(INPUT!J:J,$A17, INPUT!L:L, INT($B$3)) -> 0 | C17: =SUMIFS(INPUT!C:C, INPUT!J:J,$A17, INPUT!L:L, INT($B$3)) -> 0 | D17: =SUMIFS(INPUT!E:E, INPUT!J:J,$A17, INPUT!L:L, INT($B$3)) -> 0 | E17: =SUMIFS(INPUT!D:D, INPUT!J:J,$A17, INPUT!L:L, INT($B$3)) -> 0 | F17: =SUMIFS(INPUT!G:G, INPUT!J:J,$A17, INPUT!L:L, INT($B$3)) -> 0 | H17: TOTAL | I17: =SUM(I10:I16) -> 0 | J17: =SUM(J10:J16) -> 0 | K17: =SUM(K10:K16) -> 0 | L17: =SUM(L10:L16) -> 0 | M17: =SUM(M10:M16) -> 0
A18: TOTAL | B18: =SUM(B10:B17) -> 30 | C18: =SUM(C10:C17) -> 1823 | D18: =SUM(D10:D17) -> 926.1 | E18: =SUM(E10:E17) -> 0 | F18: =SUM(F10:F17) -> 896.9
A20: CHI TIẾT NGÀY (chỉ thợ đã chọn) | H20: TỔNG THÁNG (Selected Tech)
A21: Date | B21: Service | C21: Tip | D21: Discount % | E21: Gift | F21: Tech Share | G21: Salon Net | H21: Tech | I21: # Khách | J21: Service | K21: Tip | L21: Tech Share | M21: Salon Gross | N21: Salon Net
A22: =IFERROR(__xludf.DUMMYFUNCTION("IF($B$4=""ALL"",IFERROR(FILTER({INPUT!A:A,INPUT!C:C,INPUT!D:D,INPUT!H:H,INPUT!I:I,INPUT!E:E,INPUT!G:G},INPUT!L:L=INT($B$3)),""""),IFERROR(FILTER({INPUT!A:A,INPUT!C:C,INPUT!D:D,INPUT!H:H,INPUT!I:I,INPUT!E:E,INPUT!G:G},INPUT!J:J=$B$4,INPUT!L:L=INT($B$3)),"""&"""))"),46071.0) -> 46071 | B22: =IFERROR(__xludf.DUMMYFUNCTION("""COMPUTED_VALUE"""),57.0) -> 57 | F22: =IFERROR(__xludf.DUMMYFUNCTION("""COMPUTED_VALUE"""),34.199999999999996) -> 34.2 | G22: =IFERROR(__xludf.DUMMYFUNCTION("""COMPUTED_VALUE"""),22.8) -> 22.8 | H22: =$B$4 -> tony | I22: =IF($B$4="ALL",COUNTIFS(INPUT!L:L,">="&DATE(LEFT($B$6,4),RIGHT($B$6,2),1),INPUT!L:L,"<"&EOMONTH(DATE(LEFT($B$6,4),RIGHT($B$6,2),1),0)+1),COUNTIFS(INPUT!J:J,$B$4,INPUT!L:L,">="&DATE(LEFT($B$6,4),RIGHT($B$6,2),1),INPUT!L:L,"<"&EOMONTH(DATE(LEFT($B$6,4),RIGHT($B$6,2),1),0)+1)) -> 5 | J22: =IF($B$4="ALL",SUMIFS(INPUT!C:C,INPUT!L:L,">="&DATE(LEFT($B$6,4),RIGHT($B$6,2),1),INPUT!L:L,"<"&EOMONTH(DATE(LEFT($B$6,4),RIGHT($B$6,2),1),0)+1),SUMIFS(INPUT!C:C,INPUT!J:J,$B$4,INPUT!L:L,">="&DATE(LEFT($B$6,4),RIGHT($B$6,2),1),INPUT!L:L,"<"&EOMONTH(DATE(LEFT($B$6,4),RIGHT($B$6,2),1),0)+1)) -> 286 | K22: =IF($B$4="ALL",SUMIFS(INPUT!D:D,INPUT!L:L,">="&DATE(LEFT($B$6,4),RIGHT($B$6,2),1),INPUT!L:L,"<"&EOMONTH(DATE(LEFT($B$6,4),RIGHT($B$6,2),1),0)+1),SUMIFS(INPUT!D:D,INPUT!J:J,$B$4,INPUT!L:L,">="&DATE(LEFT($B$6,4),RIGHT($B$6,2),1),INPUT!L:L,"<"&EOMONTH(DATE(LEFT($B$6,4),RIGHT($B$6,2),1),0)+1)) -> 0 | L22: =IF($B$4="ALL",SUMIFS(INPUT!E:E,INPUT!L:L,">="&DATE(LEFT($B$6,4),RIGHT($B$6,2),1),INPUT!L:L,"<"&EOMONTH(DATE(LEFT($B$6,4),RIGHT($B$6,2),1),0)+1),SUMIFS(INPUT!E:E,INPUT!J:J,$B$4,INPUT!L:L,">="&DATE(LEFT($B$6,4),RIGHT($B$6,2),1),INPUT!L:L,"<"&EOMONTH(DATE(LEFT($B$6,4),RIGHT($B$6,2),1),0)+1)) -> 171.6 | M22: =IF($B$4="ALL",SUMIFS(INPUT!F:F,INPUT!L:L,">="&DATE(LEFT($B$6,4),RIGHT($B$6,2),1),INPUT!L:L,"<"&EOMONTH(DATE(LEFT($B$6,4),RIGHT($B$6,2),1),0)+1),SUMIFS(INPUT!F:F,INPUT!J:J,$B$4,INPUT!L:L,">="&DATE(LEFT($B$6,4),RIGHT($B$6,2),1),INPUT!L:L,"<"&EOMONTH(DATE(LEFT($B$6,4),RIGHT($B$6,2),1),0)+1)) -> 114.4 | N22: =IF($B$4="ALL",SUMIFS(INPUT!G:G,INPUT!L:L,">="&DATE(LEFT($B$6,4),RIGHT($B$6,2),1),INPUT!L:L,"<"&EOMONTH(DATE(LEFT($B$6,4),RIGHT($B$6,2),1),0)+1),SUMIFS(INPUT!G:G,INPUT!J:J,$B$4,INPUT!L:L,">="&DATE(LEFT($B$6,4),RIGHT($B$6,2),1),INPUT!L:L,"<"&EOMONTH(DATE(LEFT($B$6,4),RIGHT($B$6,2),1),0)+1)) -> 114.4
A23: =IFERROR(__xludf.DUMMYFUNCTION("""COMPUTED_VALUE"""),46071.0) -> 46071 | B23: =IFERROR(__xludf.DUMMYFUNCTION("""COMPUTED_VALUE"""),77.0) -> 77 | F23: =IFERROR(__xludf.DUMMYFUNCTION("""COMPUTED_VALUE"""),46.199999999999996) -> 46.2 | G23: =IFERROR(__xludf.DUMMYFUNCTION("""COMPUTED_VALUE"""),30.8) -> 30.8
A24: =IFERROR(__xludf.DUMMYFUNCTION("""COMPUTED_VALUE"""),46071.0) -> 46071 | B24: =IFERROR(__xludf.DUMMYFUNCTION("""COMPUTED_VALUE"""),47.0) -> 47 | F24: =IFERROR(__xludf.DUMMYFUNCTION("""COMPUTED_VALUE"""),28.2) -> 28.2 | G24: =IFERROR(__xludf.DUMMYFUNCTION("""COMPUTED_VALUE"""),18.8) -> 18.8
A25: =IFERROR(__xludf.DUMMYFUNCTION("""COMPUTED_VALUE"""),46071.0) -> 46071 | B25: =IFERROR(__xludf.DUMMYFUNCTION("""COMPUTED_VALUE"""),47.0) -> 47 | F25: =IFERROR(__xludf.DUMMYFUNCTION("""COMPUTED_VALUE"""),28.2) -> 28.2 | G25: =IFERROR(__xludf.DUMMYFUNCTION("""COMPUTED_VALUE"""),18.8) -> 18.8
A26: =IFERROR(__xludf.DUMMYFUNCTION("""COMPUTED_VALUE"""),46071.0) -> 46071 | B26: =IFERROR(__xludf.DUMMYFUNCTION("""COMPUTED_VALUE"""),62.0) -> 62 | F26: =IFERROR(__xludf.DUMMYFUNCTION("""COMPUTED_VALUE"""),37.199999999999996) -> 37.2 | G26: =IFERROR(__xludf.DUMMYFUNCTION("""COMPUTED_VALUE"""),24.8) -> 24.8
A27: =IFERROR(__xludf.DUMMYFUNCTION("""COMPUTED_VALUE"""),46071.0) -> 46071 | B27: =IFERROR(__xludf.DUMMYFUNCTION("""COMPUTED_VALUE"""),47.0) -> 47 | F27: =IFERROR(__xludf.DUMMYFUNCTION("""COMPUTED_VALUE"""),28.2) -> 28.2 | G27: =IFERROR(__xludf.DUMMYFUNCTION("""COMPUTED_VALUE"""),18.8) -> 18.8
A28: =IFERROR(__xludf.DUMMYFUNCTION("""COMPUTED_VALUE"""),46071.0) -> 46071 | B28: =IFERROR(__xludf.DUMMYFUNCTION("""COMPUTED_VALUE"""),40.0) -> 40 | F28: =IFERROR(__xludf.DUMMYFUNCTION("""COMPUTED_VALUE"""),24.0) -> 24 | G28: =IFERROR(__xludf.DUMMYFUNCTION("""COMPUTED_VALUE"""),16.0) -> 16

Sheet INPUT
A1: INPUT - 1 khách = 1 dòng. Nhập: Date (dd/mm/yyyy), Tech (dropdown hoặc gõ code RY/HA...), Service, Tip, Discount%, Gift.
A3: Date | B3: Tech | C3: Service | D3: Tip | E3: Tech Share | F3: Salon Share (gross) | G3: Salon Net | H3: Discount % | I3: Gift Card | J3: TechNorm (hidden) | K3: WeekStart(Mon) (hidden) | L3: DateOnly (hidden) | M3: MonthKey (hidden)
A4: 46054 | B4: RYAN | C4: 85 | E4: =IF(J4="","", C4 * IFERROR(VLOOKUP(J4, SETUP!$A:$D, 3, FALSE), 0)) -> 51 | F4: =IF(J4="","", C4 * IFERROR(VLOOKUP(J4, SETUP!$A:$D, 4, FALSE), 0)) -> 34 | G4: =IF(J4="","", F4 - (C4*IF(H4="",0,H4)) - IF(I4="",0,I4)) -> 34 | J4: =IF(TRIM(B4)="","",IF(ISNUMBER(SEARCH(" - ",B4)),TRIM(RIGHT(B4,LEN(B4)-FIND(" - ",B4)-2)),IFERROR(VLOOKUP(UPPER(TRIM(B4)), SETUP!$B$4:$C$11, 2, FALSE), UPPER(TRIM(B4))))) -> RYAN | K4: =IF(A4="","", INT(A4) - WEEKDAY(INT(A4),2) + 1) -> 46048 | L4: =IF(A4="","", INT(A4)) -> 46054 | M4: =IF(A4="","",TEXT(L4,"yyyy-mm")) -> 2026-02
A5: 46054 | B5: RYAN | C5: 47 | E5: =IF(J5="","", C5 * IFERROR(VLOOKUP(J5, SETUP!$A:$D, 3, FALSE), 0)) -> 28.2 | F5: =IF(J5="","", C5 * IFERROR(VLOOKUP(J5, SETUP!$A:$D, 4, FALSE), 0)) -> 18.8 | G5: =IF(J5="","", F5 - (C5*IF(H5="",0,H5)) - IF(I5="",0,I5)) -> 18.8 | J5: =IF(TRIM(B5)="","",IF(ISNUMBER(SEARCH(" - ",B5)),TRIM(RIGHT(B5,LEN(B5)-FIND(" - ",B5)-2)),IFERROR(VLOOKUP(UPPER(TRIM(B5)), SETUP!$B$4:$C$11, 2, FALSE), UPPER(TRIM(B5))))) -> RYAN | K5: =IF(A5="","", INT(A5) - WEEKDAY(INT(A5),2) + 1) -> 46048 | L5: =IF(A5="","", INT(A5)) -> 46054 | M5: =IF(A5="","",TEXT(L5,"yyyy-mm")) -> 2026-02
A6: 46054 | B6: RYAN | C6: 57 | E6: =IF(J6="","", C6 * IFERROR(VLOOKUP(J6, SETUP!$A:$D, 3, FALSE), 0)) -> 34.2 | F6: =IF(J6="","", C6 * IFERROR(VLOOKUP(J6, SETUP!$A:$D, 4, FALSE), 0)) -> 22.8 | G6: =IF(J6="","", F6 - (C6*IF(H6="",0,H6)) - IF(I6="",0,I6)) -> 22.8 | J6: =IF(TRIM(B6)="","",IF(ISNUMBER(SEARCH(" - ",B6)),TRIM(RIGHT(B6,LEN(B6)-FIND(" - ",B6)-2)),IFERROR(VLOOKUP(UPPER(TRIM(B6)), SETUP!$B$4:$C$11, 2, FALSE), UPPER(TRIM(B6))))) -> RYAN | K6: =IF(A6="","", INT(A6) - WEEKDAY(INT(A6),2) + 1) -> 46048 | L6: =IF(A6="","", INT(A6)) -> 46054 | M6: =IF(A6="","",TEXT(L6,"yyyy-mm")) -> 2026-02
A7: 46054 | B7: RYAN | C7: 70 | E7: =IF(J7="","", C7 * IFERROR(VLOOKUP(J7, SETUP!$A:$D, 3, FALSE), 0)) -> 42 | F7: =IF(J7="","", C7 * IFERROR(VLOOKUP(J7, SETUP!$A:$D, 4, FALSE), 0)) -> 28 | G7: =IF(J7="","", F7 - (C7*IF(H7="",0,H7)) - IF(I7="",0,I7)) -> 28 | J7: =IF(TRIM(B7)="","",IF(ISNUMBER(SEARCH(" - ",B7)),TRIM(RIGHT(B7,LEN(B7)-FIND(" - ",B7)-2)),IFERROR(VLOOKUP(UPPER(TRIM(B7)), SETUP!$B$4:$C$11, 2, FALSE), UPPER(TRIM(B7))))) -> RYAN | K7: =IF(A7="","", INT(A7) - WEEKDAY(INT(A7),2) + 1) -> 46048 | L7: =IF(A7="","", INT(A7)) -> 46054 | M7: =IF(A7="","",TEXT(L7,"yyyy-mm")) -> 2026-02
A8: 46054 | B8: RYAN | C8: 65 | E8: =IF(J8="","", C8 * IFERROR(VLOOKUP(J8, SETUP!$A:$D, 3, FALSE), 0)) -> 39 | F8: =IF(J8="","", C8 * IFERROR(VLOOKUP(J8, SETUP!$A:$D, 4, FALSE), 0)) -> 26 | G8: =IF(J8="","", F8 - (C8*IF(H8="",0,H8)) - IF(I8="",0,I8)) -> 26 | J8: =IF(TRIM(B8)="","",IF(ISNUMBER(SEARCH(" - ",B8)),TRIM(RIGHT(B8,LEN(B8)-FIND(" - ",B8)-2)),IFERROR(VLOOKUP(UPPER(TRIM(B8)), SETUP!$B$4:$C$11, 2, FALSE), UPPER(TRIM(B8))))) -> RYAN | K8: =IF(A8="","", INT(A8) - WEEKDAY(INT(A8),2) + 1) -> 46048 | L8: =IF(A8="","", INT(A8)) -> 46054 | M8: =IF(A8="","",TEXT(L8,"yyyy-mm")) -> 2026-02
A9: 46054 | B9: RYAN | C9: 67 | D9: 15 | E9: =IF(J9="","", C9 * IFERROR(VLOOKUP(J9, SETUP!$A:$D, 3, FALSE), 0)) -> 40.2 | F9: =IF(J9="","", C9 * IFERROR(VLOOKUP(J9, SETUP!$A:$D, 4, FALSE), 0)) -> 26.8 | G9: =IF(J9="","", F9 - (C9*IF(H9="",0,H9)) - IF(I9="",0,I9)) -> 26.8 | J9: =IF(TRIM(B9)="","",IF(ISNUMBER(SEARCH(" - ",B9)),TRIM(RIGHT(B9,LEN(B9)-FIND(" - ",B9)-2)),IFERROR(VLOOKUP(UPPER(TRIM(B9)), SETUP!$B$4:$C$11, 2, FALSE), UPPER(TRIM(B9))))) -> RYAN | K9: =IF(A9="","", INT(A9) - WEEKDAY(INT(A9),2) + 1) -> 46048 | L9: =IF(A9="","", INT(A9)) -> 46054 | M9: =IF(A9="","",TEXT(L9,"yyyy-mm")) -> 2026-02
A10: 46054 | B10: CRIS | C10: 40 | D10: 6 | E10: =IF(J10="","", C10 * IFERROR(VLOOKUP(J10, SETUP!$A:$D, 3, FALSE), 0)) -> 20 | F10: =IF(J10="","", C10 * IFERROR(VLOOKUP(J10, SETUP!$A:$D, 4, FALSE), 0)) -> 20 | G10: =IF(J10="","", F10 - (C10*IF(H10="",0,H10)) - IF(I10="",0,I10)) -> 20 | J10: =IF(TRIM(B10)="","",IF(ISNUMBER(SEARCH(" - ",B10)),TRIM(RIGHT(B10,LEN(B10)-FIND(" - ",B10)-2)),IFERROR(VLOOKUP(UPPER(TRIM(B10)), SETUP!$B$4:$C$11, 2, FALSE), UPPER(TRIM(B10))))) -> CRIS | K10: =IF(A10="","", INT(A10) - WEEKDAY(INT(A10),2) + 1) -> 46048 | L10: =IF(A10="","", INT(A10)) -> 46054 | M10: =IF(A10="","",TEXT(L10,"yyyy-mm")) -> 2026-02
A11: 46054 | B11: CRIS | C11: 40 | D11: 12 | E11: =IF(J11="","", C11 * IFERROR(VLOOKUP(J11, SETUP!$A:$D, 3, FALSE), 0)) -> 20 | F11: =IF(J11="","", C11 * IFERROR(VLOOKUP(J11, SETUP!$A:$D, 4, FALSE), 0)) -> 20 | G11: =IF(J11="","", F11 - (C11*IF(H11="",0,H11)) - IF(I11="",0,I11)) -> 20 | J11: =IF(TRIM(B11)="","",IF(ISNUMBER(SEARCH(" - ",B11)),TRIM(RIGHT(B11,LEN(B11)-FIND(" - ",B11)-2)),IFERROR(VLOOKUP(UPPER(TRIM(B11)), SETUP!$B$4:$C$11, 2, FALSE), UPPER(TRIM(B11))))) -> CRIS | K11: =IF(A11="","", INT(A11) - WEEKDAY(INT(A11),2) + 1) -> 46048 | L11: =IF(A11="","", INT(A11)) -> 46054 | M11: =IF(A11="","",TEXT(L11,"yyyy-mm")) -> 2026-02
A12: 46054 | B12: CRIS | C12: 50 | E12: =IF(J12="","", C12 * IFERROR(VLOOKUP(J12, SETUP!$A:$D, 3, FALSE), 0)) -> 25 | F12: =IF(J12="","", C12 * IFERROR(VLOOKUP(J12, SETUP!$A:$D, 4, FALSE), 0)) -> 25 | G12: =IF(J12="","", F12 - (C12*IF(H12="",0,H12)) - IF(I12="",0,I12)) -> 25 | J12: =IF(TRIM(B12)="","",IF(ISNUMBER(SEARCH(" - ",B12)),TRIM(RIGHT(B12,LEN(B12)-FIND(" - ",B12)-2)),IFERROR(VLOOKUP(UPPER(TRIM(B12)), SETUP!$B$4:$C$11, 2, FALSE), UPPER(TRIM(B12))))) -> CRIS | K12: =IF(A12="","", INT(A12) - WEEKDAY(INT(A12),2) + 1) -> 46048 | L12: =IF(A12="","", INT(A12)) -> 46054 | M12: =IF(A12="","",TEXT(L12,"yyyy-mm")) -> 2026-02
A13: 46054 | B13: CRIS | C13: 50 | E13: =IF(J13="","", C13 * IFERROR(VLOOKUP(J13, SETUP!$A:$D, 3, FALSE), 0)) -> 25 | F13: =IF(J13="","", C13 * IFERROR(VLOOKUP(J13, SETUP!$A:$D, 4, FALSE), 0)) -> 25 | G13: =IF(J13="","", F13 - (C13*IF(H13="",0,H13)) - IF(I13="",0,I13)) -> 25 | J13: =IF(TRIM(B13)="","",IF(ISNUMBER(SEARCH(" - ",B13)),TRIM(RIGHT(B13,LEN(B13)-FIND(" - ",B13)-2)),IFERROR(VLOOKUP(UPPER(TRIM(B13)), SETUP!$B$4:$C$11, 2, FALSE), UPPER(TRIM(B13))))) -> CRIS | K13: =IF(A13="","", INT(A13) - WEEKDAY(INT(A13),2) + 1) -> 46048 | L13: =IF(A13="","", INT(A13)) -> 46054 | M13: =IF(A13="","",TEXT(L13,"yyyy-mm")) -> 2026-02
A14: 46054 | B14: CRIS | C14: 40 | E14: =IF(J14="","", C14 * IFERROR(VLOOKUP(J14, SETUP!$A:$D, 3, FALSE), 0)) -> 20 | F14: =IF(J14="","", C14 * IFERROR(VLOOKUP(J14, SETUP!$A:$D, 4, FALSE), 0)) -> 20 | G14: =IF(J14="","", F14 - (C14*IF(H14="",0,H14)) - IF(I14="",0,I14)) -> 20 | J14: =IF(TRIM(B14)="","",IF(ISNUMBER(SEARCH(" - ",B14)),TRIM(RIGHT(B14,LEN(B14)-FIND(" - ",B14)-2)),IFERROR(VLOOKUP(UPPER(TRIM(B14)), SETUP!$B$4:$C$11, 2, FALSE), UPPER(TRIM(B14))))) -> CRIS | K14: =IF(A14="","", INT(A14) - WEEKDAY(INT(A14),2) + 1) -> 46048 | L14: =IF(A14="","", INT(A14)) -> 46054 | M14: =IF(A14="","",TEXT(L14,"yyyy-mm")) -> 2026-02
A15: 46054 | B15: CRIS | C15: 40 | E15: =IF(J15="","", C15 * IFERROR(VLOOKUP(J15, SETUP!$A:$D, 3, FALSE), 0)) -> 20 | F15: =IF(J15="","", C15 * IFERROR(VLOOKUP(J15, SETUP!$A:$D, 4, FALSE), 0)) -> 20 | G15: =IF(J15="","", F15 - (C15*IF(H15="",0,H15)) - IF(I15="",0,I15)) -> 20 | J15: =IF(TRIM(B15)="","",IF(ISNUMBER(SEARCH(" - ",B15)),TRIM(RIGHT(B15,LEN(B15)-FIND(" - ",B15)-2)),IFERROR(VLOOKUP(UPPER(TRIM(B15)), SETUP!$B$4:$C$11, 2, FALSE), UPPER(TRIM(B15))))) -> CRIS | K15: =IF(A15="","", INT(A15) - WEEKDAY(INT(A15),2) + 1) -> 46048 | L15: =IF(A15="","", INT(A15)) -> 46054 | M15: =IF(A15="","",TEXT(L15,"yyyy-mm")) -> 2026-02
A16: 46054 | B16: HANNI | C16: 55 | E16: =IF(J16="","", C16 * IFERROR(VLOOKUP(J16, SETUP!$A:$D, 3, FALSE), 0)) -> 0 | F16: =IF(J16="","", C16 * IFERROR(VLOOKUP(J16, SETUP!$A:$D, 4, FALSE), 0)) -> 55 | G16: =IF(J16="","", F16 - (C16*IF(H16="",0,H16)) - IF(I16="",0,I16)) -> 55 | J16: =IF(TRIM(B16)="","",IF(ISNUMBER(SEARCH(" - ",B16)),TRIM(RIGHT(B16,LEN(B16)-FIND(" - ",B16)-2)),IFERROR(VLOOKUP(UPPER(TRIM(B16)), SETUP!$B$4:$C$11, 2, FALSE), UPPER(TRIM(B16))))) -> HANNI | K16: =IF(A16="","", INT(A16) - WEEKDAY(INT(A16),2) + 1) -> 46048 | L16: =IF(A16="","", INT(A16)) -> 46054 | M16: =IF(A16="","",TEXT(L16,"yyyy-mm")) -> 2026-02
A17: 46054 | B17: HANNI | C17: 57 | E17: =IF(J17="","", C17 * IFERROR(VLOOKUP(J17, SETUP!$A:$D, 3, FALSE), 0)) -> 0 | F17: =IF(J17="","", C17 * IFERROR(VLOOKUP(J17, SETUP!$A:$D, 4, FALSE), 0)) -> 57 | G17: =IF(J17="","", F17 - (C17*IF(H17="",0,H17)) - IF(I17="",0,I17)) -> 57 | J17: =IF(TRIM(B17)="","",IF(ISNUMBER(SEARCH(" - ",B17)),TRIM(RIGHT(B17,LEN(B17)-FIND(" - ",B17)-2)),IFERROR(VLOOKUP(UPPER(TRIM(B17)), SETUP!$B$4:$C$11, 2, FALSE), UPPER(TRIM(B17))))) -> HANNI | K17: =IF(A17="","", INT(A17) - WEEKDAY(INT(A17),2) + 1) -> 46048 | L17: =IF(A17="","", INT(A17)) -> 46054 | M17: =IF(A17="","",TEXT(L17,"yyyy-mm")) -> 2026-02
A18: 46054 | B18: HANNI | C18: 52 | E18: =IF(J18="","", C18 * IFERROR(VLOOKUP(J18, SETUP!$A:$D, 3, FALSE), 0)) -> 0 | F18: =IF(J18="","", C18 * IFERROR(VLOOKUP(J18, SETUP!$A:$D, 4, FALSE), 0)) -> 52 | G18: =IF(J18="","", F18 - (C18*IF(H18="",0,H18)) - IF(I18="",0,I18)) -> 52 | J18: =IF(TRIM(B18)="","",IF(ISNUMBER(SEARCH(" - ",B18)),TRIM(RIGHT(B18,LEN(B18)-FIND(" - ",B18)-2)),IFERROR(VLOOKUP(UPPER(TRIM(B18)), SETUP!$B$4:$C$11, 2, FALSE), UPPER(TRIM(B18))))) -> HANNI | K18: =IF(A18="","", INT(A18) - WEEKDAY(INT(A18),2) + 1) -> 46048 | L18: =IF(A18="","", INT(A18)) -> 46054 | M18: =IF(A18="","",TEXT(L18,"yyyy-mm")) -> 2026-02
A19: 46054 | B19: AMY | C19: 65 | E19: =IF(J19="","", C19 * IFERROR(VLOOKUP(J19, SETUP!$A:$D, 3, FALSE), 0)) -> 39 | F19: =IF(J19="","", C19 * IFERROR(VLOOKUP(J19, SETUP!$A:$D, 4, FALSE), 0)) -> 26 | G19: =IF(J19="","", F19 - (C19*IF(H19="",0,H19)) - IF(I19="",0,I19)) -> 26 | J19: =IF(TRIM(B19)="","",IF(ISNUMBER(SEARCH(" - ",B19)),TRIM(RIGHT(B19,LEN(B19)-FIND(" - ",B19)-2)),IFERROR(VLOOKUP(UPPER(TRIM(B19)), SETUP!$B$4:$C$11, 2, FALSE), UPPER(TRIM(B19))))) -> AMY | K19: =IF(A19="","", INT(A19) - WEEKDAY(INT(A19),2) + 1) -> 46048 | L19: =IF(A19="","", INT(A19)) -> 46054 | M19: =IF(A19="","",TEXT(L19,"yyyy-mm")) -> 2026-02
A20: 46054 | B20: AMY | C20: 107 | D20: 12 | E20: =IF(J20="","", C20 * IFERROR(VLOOKUP(J20, SETUP!$A:$D, 3, FALSE), 0)) -> 64.2 | F20: =IF(J20="","", C20 * IFERROR(VLOOKUP(J20, SETUP!$A:$D, 4, FALSE), 0)) -> 42.8 | G20: =IF(J20="","", F20 - (C20*IF(H20="",0,H20)) - IF(I20="",0,I20)) -> 42.8 | J20: =IF(TRIM(B20)="","",IF(ISNUMBER(SEARCH(" - ",B20)),TRIM(RIGHT(B20,LEN(B20)-FIND(" - ",B20)-2)),IFERROR(VLOOKUP(UPPER(TRIM(B20)), SETUP!$B$4:$C$11, 2, FALSE), UPPER(TRIM(B20))))) -> AMY | K20: =IF(A20="","", INT(A20) - WEEKDAY(INT(A20),2) + 1) -> 46048 | L20: =IF(A20="","", INT(A20)) -> 46054 | M20: =IF(A20="","",TEXT(L20,"yyyy-mm")) -> 2026-02
A21: 46054 | B21: AMY | C21: 72 | D21: 7 | E21: =IF(J21="","", C21 * IFERROR(VLOOKUP(J21, SETUP!$A:$D, 3, FALSE), 0)) -> 43.2 | F21: =IF(J21="","", C21 * IFERROR(VLOOKUP(J21, SETUP!$A:$D, 4, FALSE), 0)) -> 28.8 | G21: =IF(J21="","", F21 - (C21*IF(H21="",0,H21)) - IF(I21="",0,I21)) -> 28.8 | J21: =IF(TRIM(B21)="","",IF(ISNUMBER(SEARCH(" - ",B21)),TRIM(RIGHT(B21,LEN(B21)-FIND(" - ",B21)-2)),IFERROR(VLOOKUP(UPPER(TRIM(B21)), SETUP!$B$4:$C$11, 2, FALSE), UPPER(TRIM(B21))))) -> AMY | K21: =IF(A21="","", INT(A21) - WEEKDAY(INT(A21),2) + 1) -> 46048 | L21: =IF(A21="","", INT(A21)) -> 46054 | M21: =IF(A21="","",TEXT(L21,"yyyy-mm")) -> 2026-02
A22: 46054 | B22: AMY | C22: 67 | E22: =IF(J22="","", C22 * IFERROR(VLOOKUP(J22, SETUP!$A:$D, 3, FALSE), 0)) -> 40.2 | F22: =IF(J22="","", C22 * IFERROR(VLOOKUP(J22, SETUP!$A:$D, 4, FALSE), 0)) -> 26.8 | G22: =IF(J22="","", F22 - (C22*IF(H22="",0,H22)) - IF(I22="",0,I22)) -> 26.8 | J22: =IF(TRIM(B22)="","",IF(ISNUMBER(SEARCH(" - ",B22)),TRIM(RIGHT(B22,LEN(B22)-FIND(" - ",B22)-2)),IFERROR(VLOOKUP(UPPER(TRIM(B22)), SETUP!$B$4:$C$11, 2, FALSE), UPPER(TRIM(B22))))) -> AMY | K22: =IF(A22="","", INT(A22) - WEEKDAY(INT(A22),2) + 1) -> 46048 | L22: =IF(A22="","", INT(A22)) -> 46054 | M22: =IF(A22="","",TEXT(L22,"yyyy-mm")) -> 2026-02
A23: 46055 | B23: RYAN | C23: 40 | E23: =IF(J23="","", C23 * IFERROR(VLOOKUP(J23, SETUP!$A:$D, 3, FALSE), 0)) -> 24 | F23: =IF(J23="","", C23 * IFERROR(VLOOKUP(J23, SETUP!$A:$D, 4, FALSE), 0)) -> 16 | G23: =IF(J23="","", F23 - (C23*IF(H23="",0,H23)) - IF(I23="",0,I23)) -> 16 | J23: =IF(TRIM(B23)="","",IF(ISNUMBER(SEARCH(" - ",B23)),TRIM(RIGHT(B23,LEN(B23)-FIND(" - ",B23)-2)),IFERROR(VLOOKUP(UPPER(TRIM(B23)), SETUP!$B$4:$C$11, 2, FALSE), UPPER(TRIM(B23))))) -> RYAN | K23: =IF(A23="","", INT(A23) - WEEKDAY(INT(A23),2) + 1) -> 46055 | L23: =IF(A23="","", INT(A23)) -> 46055 | M23: =IF(A23="","",TEXT(L23,"yyyy-mm")) -> 2026-02
A24: 46055 | B24: RYAN | C24: 127 | E24: =IF(J24="","", C24 * IFERROR(VLOOKUP(J24, SETUP!$A:$D, 3, FALSE), 0)) -> 76.2 | F24: =IF(J24="","", C24 * IFERROR(VLOOKUP(J24, SETUP!$A:$D, 4, FALSE), 0)) -> 50.8 | G24: =IF(J24="","", F24 - (C24*IF(H24="",0,H24)) - IF(I24="",0,I24)) -> 50.8 | J24: =IF(TRIM(B24)="","",IF(ISNUMBER(SEARCH(" - ",B24)),TRIM(RIGHT(B24,LEN(B24)-FIND(" - ",B24)-2)),IFERROR(VLOOKUP(UPPER(TRIM(B24)), SETUP!$B$4:$C$11, 2, FALSE), UPPER(TRIM(B24))))) -> RYAN | K24: =IF(A24="","", INT(A24) - WEEKDAY(INT(A24),2) + 1) -> 46055 | L24: =IF(A24="","", INT(A24)) -> 46055 | M24: =IF(A24="","",TEXT(L24,"yyyy-mm")) -> 2026-02
A25: 46055 | B25: RYAN | C25: 67 | E25: =IF(J25="","", C25 * IFERROR(VLOOKUP(J25, SETUP!$A:$D, 3, FALSE), 0)) -> 40.2 | F25: =IF(J25="","", C25 * IFERROR(VLOOKUP(J25, SETUP!$A:$D, 4, FALSE), 0)) -> 26.8 | G25: =IF(J25="","", F25 - (C25*IF(H25="",0,H25)) - IF(I25="",0,I25)) -> 26.8 | J25: =IF(TRIM(B25)="","",IF(ISNUMBER(SEARCH(" - ",B25)),TRIM(RIGHT(B25,LEN(B25)-FIND(" - ",B25)-2)),IFERROR(VLOOKUP(UPPER(TRIM(B25)), SETUP!$B$4:$C$11, 2, FALSE), UPPER(TRIM(B25))))) -> RYAN | K25: =IF(A25="","", INT(A25) - WEEKDAY(INT(A25),2) + 1) -> 46055 | L25: =IF(A25="","", INT(A25)) -> 46055 | M25: =IF(A25="","",TEXT(L25,"yyyy-mm")) -> 2026-02
A26: 46055 | B26: RYAN | C26: 47 | D26: 7 | E26: =IF(J26="","", C26 * IFERROR(VLOOKUP(J26, SETUP!$A:$D, 3, FALSE), 0)) -> 28.2 | F26: =IF(J26="","", C26 * IFERROR(VLOOKUP(J26, SETUP!$A:$D, 4, FALSE), 0)) -> 18.8 | G26: =IF(J26="","", F26 - (C26*IF(H26="",0,H26)) - IF(I26="",0,I26)) -> 18.8 | J26: =IF(TRIM(B26)="","",IF(ISNUMBER(SEARCH(" - ",B26)),TRIM(RIGHT(B26,LEN(B26)-FIND(" - ",B26)-2)),IFERROR(VLOOKUP(UPPER(TRIM(B26)), SETUP!$B$4:$C$11, 2, FALSE), UPPER(TRIM(B26))))) -> RYAN | K26: =IF(A26="","", INT(A26) - WEEKDAY(INT(A26),2) + 1) -> 46055 | L26: =IF(A26="","", INT(A26)) -> 46055 | M26: =IF(A26="","",TEXT(L26,"yyyy-mm")) -> 2026-02
A27: 46055 | B27: RYAN | C27: 47 | E27: =IF(J27="","", C27 * IFERROR(VLOOKUP(J27, SETUP!$A:$D, 3, FALSE), 0)) -> 28.2 | F27: =IF(J27="","", C27 * IFERROR(VLOOKUP(J27, SETUP!$A:$D, 4, FALSE), 0)) -> 18.8 | G27: =IF(J27="","", F27 - (C27*IF(H27="",0,H27)) - IF(I27="",0,I27)) -> 18.8 | J27: =IF(TRIM(B27)="","",IF(ISNUMBER(SEARCH(" - ",B27)),TRIM(RIGHT(B27,LEN(B27)-FIND(" - ",B27)-2)),IFERROR(VLOOKUP(UPPER(TRIM(B27)), SETUP!$B$4:$C$11, 2, FALSE), UPPER(TRIM(B27))))) -> RYAN | K27: =IF(A27="","", INT(A27) - WEEKDAY(INT(A27),2) + 1) -> 46055 | L27: =IF(A27="","", INT(A27)) -> 46055 | M27: =IF(A27="","",TEXT(L27,"yyyy-mm")) -> 2026-02
A28: 46055 | B28: HANNI | C28: 52 | E28: =IF(J28="","", C28 * IFERROR(VLOOKUP(J28, SETUP!$A:$D, 3, FALSE), 0)) -> 0 | F28: =IF(J28="","", C28 * IFERROR(VLOOKUP(J28, SETUP!$A:$D, 4, FALSE), 0)) -> 52 | G28: =IF(J28="","", F28 - (C28*IF(H28="",0,H28)) - IF(I28="",0,I28)) -> 52 | J28: =IF(TRIM(B28)="","",IF(ISNUMBER(SEARCH(" - ",B28)),TRIM(RIGHT(B28,LEN(B28)-FIND(" - ",B28)-2)),IFERROR(VLOOKUP(UPPER(TRIM(B28)), SETUP!$B$4:$C$11, 2, FALSE), UPPER(TRIM(B28))))) -> HANNI | K28: =IF(A28="","", INT(A28) - WEEKDAY(INT(A28),2) + 1) -> 46055 | L28: =IF(A28="","", INT(A28)) -> 46055 | M28: =IF(A28="","",TEXT(L28,"yyyy-mm")) -> 2026-02
A29: 46055 | B29: HANNI | C29: 95 | D29: 15 | E29: =IF(J29="","", C29 * IFERROR(VLOOKUP(J29, SETUP!$A:$D, 3, FALSE), 0)) -> 0 | F29: =IF(J29="","", C29 * IFERROR(VLOOKUP(J29, SETUP!$A:$D, 4, FALSE), 0)) -> 95 | G29: =IF(J29="","", F29 - (C29*IF(H29="",0,H29)) - IF(I29="",0,I29)) -> 95 | J29: =IF(TRIM(B29)="","",IF(ISNUMBER(SEARCH(" - ",B29)),TRIM(RIGHT(B29,LEN(B29)-FIND(" - ",B29)-2)),IFERROR(VLOOKUP(UPPER(TRIM(B29)), SETUP!$B$4:$C$11, 2, FALSE), UPPER(TRIM(B29))))) -> HANNI | K29: =IF(A29="","", INT(A29) - WEEKDAY(INT(A29),2) + 1) -> 46055 | L29: =IF(A29="","", INT(A29)) -> 46055 | M29: =IF(A29="","",TEXT(L29,"yyyy-mm")) -> 2026-02
A30: 46055 | B30: HANNI | C30: 52 | D30: 15 | E30: =IF(J30="","", C30 * IFERROR(VLOOKUP(J30, SETUP!$A:$D, 3, FALSE), 0)) -> 0 | F30: =IF(J30="","", C30 * IFERROR(VLOOKUP(J30, SETUP!$A:$D, 4, FALSE), 0)) -> 52 | G30: =IF(J30="","", F30 - (C30*IF(H30="",0,H30)) - IF(I30="",0,I30)) -> 52 | J30: =IF(TRIM(B30)="","",IF(ISNUMBER(SEARCH(" - ",B30)),TRIM(RIGHT(B30,LEN(B30)-FIND(" - ",B30)-2)),IFERROR(VLOOKUP(UPPER(TRIM(B30)), SETUP!$B$4:$C$11, 2, FALSE), UPPER(TRIM(B30))))) -> HANNI | K30: =IF(A30="","", INT(A30) - WEEKDAY(INT(A30),2) + 1) -> 46055 | L30: =IF(A30="","", INT(A30)) -> 46055 | M30: =IF(A30="","",TEXT(L30,"yyyy-mm")) -> 2026-02
A31: 46055 | B31: HANNI | C31: 47 | E31: =IF(J31="","", C31 * IFERROR(VLOOKUP(J31, SETUP!$A:$D, 3, FALSE), 0)) -> 0 | F31: =IF(J31="","", C31 * IFERROR(VLOOKUP(J31, SETUP!$A:$D, 4, FALSE), 0)) -> 47 | G31: =IF(J31="","", F31 - (C31*IF(H31="",0,H31)) - IF(I31="",0,I31)) -> 47 | J31: =IF(TRIM(B31)="","",IF(ISNUMBER(SEARCH(" - ",B31)),TRIM(RIGHT(B31,LEN(B31)-FIND(" - ",B31)-2)),IFERROR(VLOOKUP(UPPER(TRIM(B31)), SETUP!$B$4:$C$11, 2, FALSE), UPPER(TRIM(B31))))) -> HANNI | K31: =IF(A31="","", INT(A31) - WEEKDAY(INT(A31),2) + 1) -> 46055 | L31: =IF(A31="","", INT(A31)) -> 46055 | M31: =IF(A31="","",TEXT(L31,"yyyy-mm")) -> 2026-02
A32: 46055 | B32: AMY | C32: 47 | E32: =IF(J32="","", C32 * IFERROR(VLOOKUP(J32, SETUP!$A:$D, 3, FALSE), 0)) -> 28.2 | F32: =IF(J32="","", C32 * IFERROR(VLOOKUP(J32, SETUP!$A:$D, 4, FALSE), 0)) -> 18.8 | G32: =IF(J32="","", F32 - (C32*IF(H32="",0,H32)) - IF(I32="",0,I32)) -> 18.8 | J32: =IF(TRIM(B32)="","",IF(ISNUMBER(SEARCH(" - ",B32)),TRIM(RIGHT(B32,LEN(B32)-FIND(" - ",B32)-2)),IFERROR(VLOOKUP(UPPER(TRIM(B32)), SETUP!$B$4:$C$11, 2, FALSE), UPPER(TRIM(B32))))) -> AMY | K32: =IF(A32="","", INT(A32) - WEEKDAY(INT(A32),2) + 1) -> 46055 | L32: =IF(A32="","", INT(A32)) -> 46055 | M32: =IF(A32="","",TEXT(L32,"yyyy-mm")) -> 2026-02
A33: 46055 | B33: AMY | C33: 57 | E33: =IF(J33="","", C33 * IFERROR(VLOOKUP(J33, SETUP!$A:$D, 3, FALSE), 0)) -> 34.2 | F33: =IF(J33="","", C33 * IFERROR(VLOOKUP(J33, SETUP!$A:$D, 4, FALSE), 0)) -> 22.8 | G33: =IF(J33="","", F33 - (C33*IF(H33="",0,H33)) - IF(I33="",0,I33)) -> 22.8 | J33: =IF(TRIM(B33)="","",IF(ISNUMBER(SEARCH(" - ",B33)),TRIM(RIGHT(B33,LEN(B33)-FIND(" - ",B33)-2)),IFERROR(VLOOKUP(UPPER(TRIM(B33)), SETUP!$B$4:$C$11, 2, FALSE), UPPER(TRIM(B33))))) -> AMY | K33: =IF(A33="","", INT(A33) - WEEKDAY(INT(A33),2) + 1) -> 46055 | L33: =IF(A33="","", INT(A33)) -> 46055 | M33: =IF(A33="","",TEXT(L33,"yyyy-mm")) -> 2026-02
A34: 46055 | B34: AMY | C34: 52 | E34: =IF(J34="","", C34 * IFERROR(VLOOKUP(J34, SETUP!$A:$D, 3, FALSE), 0)) -> 31.2 | F34: =IF(J34="","", C34 * IFERROR(VLOOKUP(J34, SETUP!$A:$D, 4, FALSE), 0)) -> 20.8 | G34: =IF(J34="","", F34 - (C34*IF(H34="",0,H34)) - IF(I34="",0,I34)) -> 20.8 | J34: =IF(TRIM(B34)="","",IF(ISNUMBER(SEARCH(" - ",B34)),TRIM(RIGHT(B34,LEN(B34)-FIND(" - ",B34)-2)),IFERROR(VLOOKUP(UPPER(TRIM(B34)), SETUP!$B$4:$C$11, 2, FALSE), UPPER(TRIM(B34))))) -> AMY | K34: =IF(A34="","", INT(A34) - WEEKDAY(INT(A34),2) + 1) -> 46055 | L34: =IF(A34="","", INT(A34)) -> 46055 | M34: =IF(A34="","",TEXT(L34,"yyyy-mm")) -> 2026-02
A35: 46055 | B35: AMY | C35: 10 | E35: =IF(J35="","", C35 * IFERROR(VLOOKUP(J35, SETUP!$A:$D, 3, FALSE), 0)) -> 6 | F35: =IF(J35="","", C35 * IFERROR(VLOOKUP(J35, SETUP!$A:$D, 4, FALSE), 0)) -> 4 | G35: =IF(J35="","", F35 - (C35*IF(H35="",0,H35)) - IF(I35="",0,I35)) -> 4 | J35: =IF(TRIM(B35)="","",IF(ISNUMBER(SEARCH(" - ",B35)),TRIM(RIGHT(B35,LEN(B35)-FIND(" - ",B35)-2)),IFERROR(VLOOKUP(UPPER(TRIM(B35)), SETUP!$B$4:$C$11, 2, FALSE), UPPER(TRIM(B35))))) -> AMY | K35: =IF(A35="","", INT(A35) - WEEKDAY(INT(A35),2) + 1) -> 46055 | L35: =IF(A35="","", INT(A35)) -> 46055 | M35: =IF(A35="","",TEXT(L35,"yyyy-mm")) -> 2026-02
A36: 46055 | B36: AMY | C36: 62 | D36: 7 | E36: =IF(J36="","", C36 * IFERROR(VLOOKUP(J36, SETUP!$A:$D, 3, FALSE), 0)) -> 37.2 | F36: =IF(J36="","", C36 * IFERROR(VLOOKUP(J36, SETUP!$A:$D, 4, FALSE), 0)) -> 24.8 | G36: =IF(J36="","", F36 - (C36*IF(H36="",0,H36)) - IF(I36="",0,I36)) -> 24.8 | J36: =IF(TRIM(B36)="","",IF(ISNUMBER(SEARCH(" - ",B36)),TRIM(RIGHT(B36,LEN(B36)-FIND(" - ",B36)-2)),IFERROR(VLOOKUP(UPPER(TRIM(B36)), SETUP!$B$4:$C$11, 2, FALSE), UPPER(TRIM(B36))))) -> AMY | K36: =IF(A36="","", INT(A36) - WEEKDAY(INT(A36),2) + 1) -> 46055 | L36: =IF(A36="","", INT(A36)) -> 46055 | M36: =IF(A36="","",TEXT(L36,"yyyy-mm")) -> 2026-02
A37: 46055 | B37: AMY | C37: 40 | E37: =IF(J37="","", C37 * IFERROR(VLOOKUP(J37, SETUP!$A:$D, 3, FALSE), 0)) -> 24 | F37: =IF(J37="","", C37 * IFERROR(VLOOKUP(J37, SETUP!$A:$D, 4, FALSE), 0)) -> 16 | G37: =IF(J37="","", F37 - (C37*IF(H37="",0,H37)) - IF(I37="",0,I37)) -> 16 | J37: =IF(TRIM(B37)="","",IF(ISNUMBER(SEARCH(" - ",B37)),TRIM(RIGHT(B37,LEN(B37)-FIND(" - ",B37)-2)),IFERROR(VLOOKUP(UPPER(TRIM(B37)), SETUP!$B$4:$C$11, 2, FALSE), UPPER(TRIM(B37))))) -> AMY | K37: =IF(A37="","", INT(A37) - WEEKDAY(INT(A37),2) + 1) -> 46055 | L37: =IF(A37="","", INT(A37)) -> 46055 | M37: =IF(A37="","",TEXT(L37,"yyyy-mm")) -> 2026-02
A38: 46055 | B38: AMY | C38: 47 | E38: =IF(J38="","", C38 * IFERROR(VLOOKUP(J38, SETUP!$A:$D, 3, FALSE), 0)) -> 28.2 | F38: =IF(J38="","", C38 * IFERROR(VLOOKUP(J38, SETUP!$A:$D, 4, FALSE), 0)) -> 18.8 | G38: =IF(J38="","", F38 - (C38*IF(H38="",0,H38)) - IF(I38="",0,I38)) -> 18.8 | J38: =IF(TRIM(B38)="","",IF(ISNUMBER(SEARCH(" - ",B38)),TRIM(RIGHT(B38,LEN(B38)-FIND(" - ",B38)-2)),IFERROR(VLOOKUP(UPPER(TRIM(B38)), SETUP!$B$4:$C$11, 2, FALSE), UPPER(TRIM(B38))))) -> AMY | K38: =IF(A38="","", INT(A38) - WEEKDAY(INT(A38),2) + 1) -> 46055 | L38: =IF(A38="","", INT(A38)) -> 46055 | M38: =IF(A38="","",TEXT(L38,"yyyy-mm")) -> 2026-02
A39: 46055 | B39: TONY | C39: 47 | E39: =IF(J39="","", C39 * IFERROR(VLOOKUP(J39, SETUP!$A:$D, 3, FALSE), 0)) -> 28.2 | F39: =IF(J39="","", C39 * IFERROR(VLOOKUP(J39, SETUP!$A:$D, 4, FALSE), 0)) -> 18.8 | G39: =IF(J39="","", F39 - (C39*IF(H39="",0,H39)) - IF(I39="",0,I39)) -> 18.8 | J39: =IF(TRIM(B39)="","",IF(ISNUMBER(SEARCH(" - ",B39)),TRIM(RIGHT(B39,LEN(B39)-FIND(" - ",B39)-2)),IFERROR(VLOOKUP(UPPER(TRIM(B39)), SETUP!$B$4:$C$11, 2, FALSE), UPPER(TRIM(B39))))) -> TONY | K39: =IF(A39="","", INT(A39) - WEEKDAY(INT(A39),2) + 1) -> 46055 | L39: =IF(A39="","", INT(A39)) -> 46055 | M39: =IF(A39="","",TEXT(L39,"yyyy-mm")) -> 2026-02
A40: 46055 | B40: TONY | C40: 70 | D40: 10 | E40: =IF(J40="","", C40 * IFERROR(VLOOKUP(J40, SETUP!$A:$D, 3, FALSE), 0)) -> 42 | F40: =IF(J40="","", C40 * IFERROR(VLOOKUP(J40, SETUP!$A:$D, 4, FALSE), 0)) -> 28 | G40: =IF(J40="","", F40 - (C40*IF(H40="",0,H40)) - IF(I40="",0,I40)) -> 28 | J40: =IF(TRIM(B40)="","",IF(ISNUMBER(SEARCH(" - ",B40)),TRIM(RIGHT(B40,LEN(B40)-FIND(" - ",B40)-2)),IFERROR(VLOOKUP(UPPER(TRIM(B40)), SETUP!$B$4:$C$11, 2, FALSE), UPPER(TRIM(B40))))) -> TONY | K40: =IF(A40="","", INT(A40) - WEEKDAY(INT(A40),2) + 1) -> 46055 | L40: =IF(A40="","", INT(A40)) -> 46055 | M40: =IF(A40="","",TEXT(L40,"yyyy-mm")) -> 2026-02
A41: 46055 | B41: TONY | C41: 62 | E41: =IF(J41="","", C41 * IFERROR(VLOOKUP(J41, SETUP!$A:$D, 3, FALSE), 0)) -> 37.2 | F41: =IF(J41="","", C41 * IFERROR(VLOOKUP(J41, SETUP!$A:$D, 4, FALSE), 0)) -> 24.8 | G41: =IF(J41="","", F41 - (C41*IF(H41="",0,H41)) - IF(I41="",0,I41)) -> 24.8 | J41: =IF(TRIM(B41)="","",IF(ISNUMBER(SEARCH(" - ",B41)),TRIM(RIGHT(B41,LEN(B41)-FIND(" - ",B41)-2)),IFERROR(VLOOKUP(UPPER(TRIM(B41)), SETUP!$B$4:$C$11, 2, FALSE), UPPER(TRIM(B41))))) -> TONY | K41: =IF(A41="","", INT(A41) - WEEKDAY(INT(A41),2) + 1) -> 46055 | L41: =IF(A41="","", INT(A41)) -> 46055 | M41: =IF(A41="","",TEXT(L41,"yyyy-mm")) -> 2026-02
...

Sheet DAILY_VIEW
A1: DAILY_VIEW - Chọn 1 ngày -> thấy chi tiết từng khách + tổng theo thợ
A3: Selected Date: | B3: 46082
A5: Date | B5: Tech | C5: Service | D5: Discount % | E5: Gift Card | F5: Tip | G5: Tech Share | H5: Salon Share | I5: Salon Net | L5: Tech | M5: # Khách | N5: Service | O5: Tech Share | P5: Tip | Q5: Salon Net
A6: =IFERROR(__xludf.DUMMYFUNCTION("IFERROR(FILTER({INPUT!A:A,INPUT!J:J,INPUT!C:C,INPUT!H:H,INPUT!I:I,INPUT!D:D,INPUT!E:E,INPUT!F:F,INPUT!G:G}, INPUT!L:L=INT($B$3)), """")"),46082.0) -> 46082 | B6: =IFERROR(__xludf.DUMMYFUNCTION("""COMPUTED_VALUE"""),"RYAN") -> RYAN | C6: =IFERROR(__xludf.DUMMYFUNCTION("""COMPUTED_VALUE"""),72.0) -> 72 | G6: =IFERROR(__xludf.DUMMYFUNCTION("""COMPUTED_VALUE"""),43.199999999999996) -> 43.2 | H6: =IFERROR(__xludf.DUMMYFUNCTION("""COMPUTED_VALUE"""),28.8) -> 28.8 | I6: =IFERROR(__xludf.DUMMYFUNCTION("""COMPUTED_VALUE"""),28.8) -> 28.8 | L6: KEN | M6: =COUNTIFS(INPUT!J:J,$L6, INPUT!L:L, INT($B$3)) -> 0 | N6: =SUMIFS(INPUT!C:C, INPUT!J:J,$L6, INPUT!L:L, INT($B$3)) -> 0 | O6: =SUMIFS(INPUT!E:E, INPUT!J:J,$L6, INPUT!L:L, INT($B$3)) -> 0 | P6: =SUMIFS(INPUT!D:D, INPUT!J:J,$L6, INPUT!L:L, INT($B$3)) -> 0 | Q6: =SUMIFS(INPUT!G:G, INPUT!J:J,$L6, INPUT!L:L, INT($B$3)) -> 0
A7: =IFERROR(__xludf.DUMMYFUNCTION("""COMPUTED_VALUE"""),46082.0) -> 46082 | B7: =IFERROR(__xludf.DUMMYFUNCTION("""COMPUTED_VALUE"""),"RYAN") -> RYAN | C7: =IFERROR(__xludf.DUMMYFUNCTION("""COMPUTED_VALUE"""),57.0) -> 57 | G7: =IFERROR(__xludf.DUMMYFUNCTION("""COMPUTED_VALUE"""),34.199999999999996) -> 34.2 | H7: =IFERROR(__xludf.DUMMYFUNCTION("""COMPUTED_VALUE"""),22.8) -> 22.8 | I7: =IFERROR(__xludf.DUMMYFUNCTION("""COMPUTED_VALUE"""),22.8) -> 22.8 | L7: RYAN | M7: =COUNTIFS(INPUT!J:J,$L7, INPUT!L:L, INT($B$3)) -> 4 | N7: =SUMIFS(INPUT!C:C, INPUT!J:J,$L7, INPUT!L:L, INT($B$3)) -> 259 | O7: =SUMIFS(INPUT!E:E, INPUT!J:J,$L7, INPUT!L:L, INT($B$3)) -> 155.4 | P7: =SUMIFS(INPUT!D:D, INPUT!J:J,$L7, INPUT!L:L, INT($B$3)) -> 0 | Q7: =SUMIFS(INPUT!G:G, INPUT!J:J,$L7, INPUT!L:L, INT($B$3)) -> 103.6
A8: =IFERROR(__xludf.DUMMYFUNCTION("""COMPUTED_VALUE"""),46082.0) -> 46082 | B8: =IFERROR(__xludf.DUMMYFUNCTION("""COMPUTED_VALUE"""),"RYAN") -> RYAN | C8: =IFERROR(__xludf.DUMMYFUNCTION("""COMPUTED_VALUE"""),65.0) -> 65 | G8: =IFERROR(__xludf.DUMMYFUNCTION("""COMPUTED_VALUE"""),39.0) -> 39 | H8: =IFERROR(__xludf.DUMMYFUNCTION("""COMPUTED_VALUE"""),26.0) -> 26 | I8: =IFERROR(__xludf.DUMMYFUNCTION("""COMPUTED_VALUE"""),26.0) -> 26 | L8: CRIS | M8: =COUNTIFS(INPUT!J:J,$L8, INPUT!L:L, INT($B$3)) -> 3 | N8: =SUMIFS(INPUT!C:C, INPUT!J:J,$L8, INPUT!L:L, INT($B$3)) -> 135 | O8: =SUMIFS(INPUT!E:E, INPUT!J:J,$L8, INPUT!L:L, INT($B$3)) -> 67.5 | P8: =SUMIFS(INPUT!D:D, INPUT!J:J,$L8, INPUT!L:L, INT($B$3)) -> 0 | Q8: =SUMIFS(INPUT!G:G, INPUT!J:J,$L8, INPUT!L:L, INT($B$3)) -> 67.5
A9: =IFERROR(__xludf.DUMMYFUNCTION("""COMPUTED_VALUE"""),46082.0) -> 46082 | B9: =IFERROR(__xludf.DUMMYFUNCTION("""COMPUTED_VALUE"""),"CRIS") -> CRIS | C9: =IFERROR(__xludf.DUMMYFUNCTION("""COMPUTED_VALUE"""),55.0) -> 55 | G9: =IFERROR(__xludf.DUMMYFUNCTION("""COMPUTED_VALUE"""),27.5) -> 27.5 | H9: =IFERROR(__xludf.DUMMYFUNCTION("""COMPUTED_VALUE"""),27.5) -> 27.5 | I9: =IFERROR(__xludf.DUMMYFUNCTION("""COMPUTED_VALUE"""),27.5) -> 27.5 | L9: HANNI | M9: =COUNTIFS(INPUT!J:J,$L9, INPUT!L:L, INT($B$3)) -> 0 | N9: =SUMIFS(INPUT!C:C, INPUT!J:J,$L9, INPUT!L:L, INT($B$3)) -> 0 | O9: =SUMIFS(INPUT!E:E, INPUT!J:J,$L9, INPUT!L:L, INT($B$3)) -> 0 | P9: =SUMIFS(INPUT!D:D, INPUT!J:J,$L9, INPUT!L:L, INT($B$3)) -> 0 | Q9: =SUMIFS(INPUT!G:G, INPUT!J:J,$L9, INPUT!L:L, INT($B$3)) -> 0
A10: =IFERROR(__xludf.DUMMYFUNCTION("""COMPUTED_VALUE"""),46082.0) -> 46082 | B10: =IFERROR(__xludf.DUMMYFUNCTION("""COMPUTED_VALUE"""),"CRIS") -> CRIS | C10: =IFERROR(__xludf.DUMMYFUNCTION("""COMPUTED_VALUE"""),30.0) -> 30 | G10: =IFERROR(__xludf.DUMMYFUNCTION("""COMPUTED_VALUE"""),15.0) -> 15 | H10: =IFERROR(__xludf.DUMMYFUNCTION("""COMPUTED_VALUE"""),15.0) -> 15 | I10: =IFERROR(__xludf.DUMMYFUNCTION("""COMPUTED_VALUE"""),15.0) -> 15 | L10: AMY | M10: =COUNTIFS(INPUT!J:J,$L10, INPUT!L:L, INT($B$3)) -> 5 | N10: =SUMIFS(INPUT!C:C, INPUT!J:J,$L10, INPUT!L:L, INT($B$3)) -> 236 | O10: =SUMIFS(INPUT!E:E, INPUT!J:J,$L10, INPUT!L:L, INT($B$3)) -> 141.6 | P10: =SUMIFS(INPUT!D:D, INPUT!J:J,$L10, INPUT!L:L, INT($B$3)) -> 0 | Q10: =SUMIFS(INPUT!G:G, INPUT!J:J,$L10, INPUT!L:L, INT($B$3)) -> 94.4
A11: =IFERROR(__xludf.DUMMYFUNCTION("""COMPUTED_VALUE"""),46082.0) -> 46082 | B11: =IFERROR(__xludf.DUMMYFUNCTION("""COMPUTED_VALUE"""),"CRIS") -> CRIS | C11: =IFERROR(__xludf.DUMMYFUNCTION("""COMPUTED_VALUE"""),50.0) -> 50 | G11: =IFERROR(__xludf.DUMMYFUNCTION("""COMPUTED_VALUE"""),25.0) -> 25 | H11: =IFERROR(__xludf.DUMMYFUNCTION("""COMPUTED_VALUE"""),25.0) -> 25 | I11: =IFERROR(__xludf.DUMMYFUNCTION("""COMPUTED_VALUE"""),25.0) -> 25 | L11: TONY | M11: =COUNTIFS(INPUT!J:J,$L11, INPUT!L:L, INT($B$3)) -> 5 | N11: =SUMIFS(INPUT!C:C, INPUT!J:J,$L11, INPUT!L:L, INT($B$3)) -> 286 | O11: =SUMIFS(INPUT!E:E, INPUT!J:J,$L11, INPUT!L:L, INT($B$3)) -> 171.6 | P11: =SUMIFS(INPUT!D:D, INPUT!J:J,$L11, INPUT!L:L, INT($B$3)) -> 0 | Q11: =SUMIFS(INPUT!G:G, INPUT!J:J,$L11, INPUT!L:L, INT($B$3)) -> 114.4
A12: =IFERROR(__xludf.DUMMYFUNCTION("""COMPUTED_VALUE"""),46082.0) -> 46082 | B12: =IFERROR(__xludf.DUMMYFUNCTION("""COMPUTED_VALUE"""),"AMY") -> AMY | C12: =IFERROR(__xludf.DUMMYFUNCTION("""COMPUTED_VALUE"""),55.0) -> 55 | G12: =IFERROR(__xludf.DUMMYFUNCTION("""COMPUTED_VALUE"""),33.0) -> 33 | H12: =IFERROR(__xludf.DUMMYFUNCTION("""COMPUTED_VALUE"""),22.0) -> 22 | I12: =IFERROR(__xludf.DUMMYFUNCTION("""COMPUTED_VALUE"""),22.0) -> 22 | L12: STEVEN | M12: =COUNTIFS(INPUT!J:J,$L12, INPUT!L:L, INT($B$3)) -> 0 | N12: =SUMIFS(INPUT!C:C, INPUT!J:J,$L12, INPUT!L:L, INT($B$3)) -> 0 | O12: =SUMIFS(INPUT!E:E, INPUT!J:J,$L12, INPUT!L:L, INT($B$3)) -> 0 | P12: =SUMIFS(INPUT!D:D, INPUT!J:J,$L12, INPUT!L:L, INT($B$3)) -> 0 | Q12: =SUMIFS(INPUT!G:G, INPUT!J:J,$L12, INPUT!L:L, INT($B$3)) -> 0
A13: =IFERROR(__xludf.DUMMYFUNCTION("""COMPUTED_VALUE"""),46082.0) -> 46082 | B13: =IFERROR(__xludf.DUMMYFUNCTION("""COMPUTED_VALUE"""),"AMY") -> AMY | C13: =IFERROR(__xludf.DUMMYFUNCTION("""COMPUTED_VALUE"""),60.0) -> 60 | G13: =IFERROR(__xludf.DUMMYFUNCTION("""COMPUTED_VALUE"""),36.0) -> 36 | H13: =IFERROR(__xludf.DUMMYFUNCTION("""COMPUTED_VALUE"""),24.0) -> 24 | I13: =IFERROR(__xludf.DUMMYFUNCTION("""COMPUTED_VALUE"""),24.0) -> 24 | L13: BEN | M13: =COUNTIFS(INPUT!J:J,$L13, INPUT!L:L, INT($B$3)) -> 0 | N13: =SUMIFS(INPUT!C:C, INPUT!J:J,$L13, INPUT!L:L, INT($B$3)) -> 0 | O13: =SUMIFS(INPUT!E:E, INPUT!J:J,$L13, INPUT!L:L, INT($B$3)) -> 0 | P13: =SUMIFS(INPUT!D:D, INPUT!J:J,$L13, INPUT!L:L, INT($B$3)) -> 0 | Q13: =SUMIFS(INPUT!G:G, INPUT!J:J,$L13, INPUT!L:L, INT($B$3)) -> 0
A14: =IFERROR(__xludf.DUMMYFUNCTION("""COMPUTED_VALUE"""),46082.0) -> 46082 | B14: =IFERROR(__xludf.DUMMYFUNCTION("""COMPUTED_VALUE"""),"AMY") -> AMY | C14: =IFERROR(__xludf.DUMMYFUNCTION("""COMPUTED_VALUE"""),35.0) -> 35 | G14: =IFERROR(__xludf.DUMMYFUNCTION("""COMPUTED_VALUE"""),21.0) -> 21 | H14: =IFERROR(__xludf.DUMMYFUNCTION("""COMPUTED_VALUE"""),14.0) -> 14 | I14: =IFERROR(__xludf.DUMMYFUNCTION("""COMPUTED_VALUE"""),14.0) -> 14
A15: =IFERROR(__xludf.DUMMYFUNCTION("""COMPUTED_VALUE"""),46082.0) -> 46082 | B15: =IFERROR(__xludf.DUMMYFUNCTION("""COMPUTED_VALUE"""),"AMY") -> AMY | C15: =IFERROR(__xludf.DUMMYFUNCTION("""COMPUTED_VALUE"""),57.0) -> 57 | G15: =IFERROR(__xludf.DUMMYFUNCTION("""COMPUTED_VALUE"""),34.199999999999996) -> 34.2 | H15: =IFERROR(__xludf.DUMMYFUNCTION("""COMPUTED_VALUE"""),22.8) -> 22.8 | I15: =IFERROR(__xludf.DUMMYFUNCTION("""COMPUTED_VALUE"""),22.8) -> 22.8 | L15: TOTAL | M15: =SUM(M6:M14) -> 17 | N15: =SUM(N6:N14) -> 916 | O15: =SUM(O6:O14) -> 536.1 | P15: =SUM(P6:P14) -> 0 | Q15: =SUM(Q6:Q14) -> 379.9
A16: =IFERROR(__xludf.DUMMYFUNCTION("""COMPUTED_VALUE"""),46082.0) -> 46082 | B16: =IFERROR(__xludf.DUMMYFUNCTION("""COMPUTED_VALUE"""),"TONY") -> TONY | C16: =IFERROR(__xludf.DUMMYFUNCTION("""COMPUTED_VALUE"""),65.0) -> 65 | G16: =IFERROR(__xludf.DUMMYFUNCTION("""COMPUTED_VALUE"""),39.0) -> 39 | H16: =IFERROR(__xludf.DUMMYFUNCTION("""COMPUTED_VALUE"""),26.0) -> 26 | I16: =IFERROR(__xludf.DUMMYFUNCTION("""COMPUTED_VALUE"""),26.0) -> 26
A17: =IFERROR(__xludf.DUMMYFUNCTION("""COMPUTED_VALUE"""),46082.0) -> 46082 | B17: =IFERROR(__xludf.DUMMYFUNCTION("""COMPUTED_VALUE"""),"TONY") -> TONY | C17: =IFERROR(__xludf.DUMMYFUNCTION("""COMPUTED_VALUE"""),57.0) -> 57 | G17: =IFERROR(__xludf.DUMMYFUNCTION("""COMPUTED_VALUE"""),34.199999999999996) -> 34.2 | H17: =IFERROR(__xludf.DUMMYFUNCTION("""COMPUTED_VALUE"""),22.8) -> 22.8 | I17: =IFERROR(__xludf.DUMMYFUNCTION("""COMPUTED_VALUE"""),22.8) -> 22.8
A18: =IFERROR(__xludf.DUMMYFUNCTION("""COMPUTED_VALUE"""),46082.0) -> 46082 | B18: =IFERROR(__xludf.DUMMYFUNCTION("""COMPUTED_VALUE"""),"TONY") -> TONY | C18: =IFERROR(__xludf.DUMMYFUNCTION("""COMPUTED_VALUE"""),35.0) -> 35 | G18: =IFERROR(__xludf.DUMMYFUNCTION("""COMPUTED_VALUE"""),21.0) -> 21 | H18: =IFERROR(__xludf.DUMMYFUNCTION("""COMPUTED_VALUE"""),14.0) -> 14 | I18: =IFERROR(__xludf.DUMMYFUNCTION("""COMPUTED_VALUE"""),14.0) -> 14
A19: =IFERROR(__xludf.DUMMYFUNCTION("""COMPUTED_VALUE"""),46082.0) -> 46082 | B19: =IFERROR(__xludf.DUMMYFUNCTION("""COMPUTED_VALUE"""),"TONY") -> TONY | C19: =IFERROR(__xludf.DUMMYFUNCTION("""COMPUTED_VALUE"""),57.0) -> 57 | G19: =IFERROR(__xludf.DUMMYFUNCTION("""COMPUTED_VALUE"""),34.199999999999996) -> 34.2 | H19: =IFERROR(__xludf.DUMMYFUNCTION("""COMPUTED_VALUE"""),22.8) -> 22.8 | I19: =IFERROR(__xludf.DUMMYFUNCTION("""COMPUTED_VALUE"""),22.8) -> 22.8
A20: =IFERROR(__xludf.DUMMYFUNCTION("""COMPUTED_VALUE"""),46082.0) -> 46082 | B20: =IFERROR(__xludf.DUMMYFUNCTION("""COMPUTED_VALUE"""),"AMY") -> AMY | C20: =IFERROR(__xludf.DUMMYFUNCTION("""COMPUTED_VALUE"""),29.0) -> 29 | G20: =IFERROR(__xludf.DUMMYFUNCTION("""COMPUTED_VALUE"""),17.4) -> 17.4 | H20: =IFERROR(__xludf.DUMMYFUNCTION("""COMPUTED_VALUE"""),11.600000000000001) -> 11.6 | I20: =IFERROR(__xludf.DUMMYFUNCTION("""COMPUTED_VALUE"""),11.600000000000001) -> 11.6
A21: =IFERROR(__xludf.DUMMYFUNCTION("""COMPUTED_VALUE"""),46082.0) -> 46082 | B21: =IFERROR(__xludf.DUMMYFUNCTION("""COMPUTED_VALUE"""),"RYAN") -> RYAN | C21: =IFERROR(__xludf.DUMMYFUNCTION("""COMPUTED_VALUE"""),65.0) -> 65 | G21: =IFERROR(__xludf.DUMMYFUNCTION("""COMPUTED_VALUE"""),39.0) -> 39 | H21: =IFERROR(__xludf.DUMMYFUNCTION("""COMPUTED_VALUE"""),26.0) -> 26 | I21: =IFERROR(__xludf.DUMMYFUNCTION("""COMPUTED_VALUE"""),26.0) -> 26
A22: =IFERROR(__xludf.DUMMYFUNCTION("""COMPUTED_VALUE"""),46082.0) -> 46082 | B22: =IFERROR(__xludf.DUMMYFUNCTION("""COMPUTED_VALUE"""),"TONY") -> TONY | C22: =IFERROR(__xludf.DUMMYFUNCTION("""COMPUTED_VALUE"""),72.0) -> 72 | G22: =IFERROR(__xludf.DUMMYFUNCTION("""COMPUTED_VALUE"""),43.199999999999996) -> 43.2 | H22: =IFERROR(__xludf.DUMMYFUNCTION("""COMPUTED_VALUE"""),28.8) -> 28.8 | I22: =IFERROR(__xludf.DUMMYFUNCTION("""COMPUTED_VALUE"""),28.8) -> 28.8
A23: =IFERROR(__xludf.DUMMYFUNCTION("""COMPUTED_VALUE"""),46082.0) -> 46082 | B23: =IFERROR(__xludf.DUMMYFUNCTION("""COMPUTED_VALUE"""),"") | G23: =IFERROR(__xludf.DUMMYFUNCTION("""COMPUTED_VALUE"""),"") | H23: =IFERROR(__xludf.DUMMYFUNCTION("""COMPUTED_VALUE"""),"") | I23: =IFERROR(__xludf.DUMMYFUNCTION("""COMPUTED_VALUE"""),"")

Sheet WEEKLY_SUMMARY
A1: WEEKLY_SUMMARY - Chọn WeekStart (Mon) -> tổng theo thợ
A3: WeekStart (Mon): | B3: 46055 | D3: Selected Tech: | E3: ryan | H3: (WeekStart = Thứ 2)
A5: Tech | B5: # Khách | C5: Service | D5: Tech Share | E5: Tip | F5: Salon Net
A6: KEN | B6: =COUNTIFS(INPUT!J:J,$A6, INPUT!K:K, $B$3) -> 10 | C6: =SUMIFS(INPUT!C:C, INPUT!J:J,$A6, INPUT!K:K, $B$3) -> 586 | D6: =SUMIFS(INPUT!E:E, INPUT!J:J,$A6, INPUT!K:K, $B$3) -> 0 | E6: =SUMIFS(INPUT!D:D, INPUT!J:J,$A6, INPUT!K:K, $B$3) -> 0 | F6: =SUMIFS(INPUT!G:G, INPUT!J:J,$A6, INPUT!K:K, $B$3) -> 586
A7: RYAN | B7: =COUNTIFS(INPUT!J:J,$A7, INPUT!K:K, $B$3) -> 44 | C7: =SUMIFS(INPUT!C:C, INPUT!J:J,$A7, INPUT!K:K, $B$3) -> 3078 | D7: =SUMIFS(INPUT!E:E, INPUT!J:J,$A7, INPUT!K:K, $B$3) -> 1846.8 | E7: =SUMIFS(INPUT!D:D, INPUT!J:J,$A7, INPUT!K:K, $B$3) -> 63 | F7: =SUMIFS(INPUT!G:G, INPUT!J:J,$A7, INPUT!K:K, $B$3) -> 1231.2
A8: CRIS | B8: =COUNTIFS(INPUT!J:J,$A8, INPUT!K:K, $B$3) -> 26 | C8: =SUMIFS(INPUT!C:C, INPUT!J:J,$A8, INPUT!K:K, $B$3) -> 1377 | D8: =SUMIFS(INPUT!E:E, INPUT!J:J,$A8, INPUT!K:K, $B$3) -> 688.5 | E8: =SUMIFS(INPUT!D:D, INPUT!J:J,$A8, INPUT!K:K, $B$3) -> 20 | F8: =SUMIFS(INPUT!G:G, INPUT!J:J,$A8, INPUT!K:K, $B$3) -> 688.5
A9: HANNI | B9: =COUNTIFS(INPUT!J:J,$A9, INPUT!K:K, $B$3) -> 18 | C9: =SUMIFS(INPUT!C:C, INPUT!J:J,$A9, INPUT!K:K, $B$3) -> 1156 | D9: =SUMIFS(INPUT!E:E, INPUT!J:J,$A9, INPUT!K:K, $B$3) -> 0 | E9: =SUMIFS(INPUT!D:D, INPUT!J:J,$A9, INPUT!K:K, $B$3) -> 40 | F9: =SUMIFS(INPUT!G:G, INPUT!J:J,$A9, INPUT!K:K, $B$3) -> 1156
A10: AMY | B10: =COUNTIFS(INPUT!J:J,$A10, INPUT!K:K, $B$3) -> 45 | C10: =SUMIFS(INPUT!C:C, INPUT!J:J,$A10, INPUT!K:K, $B$3) -> 3072 | D10: =SUMIFS(INPUT!E:E, INPUT!J:J,$A10, INPUT!K:K, $B$3) -> 1843.2 | E10: =SUMIFS(INPUT!D:D, INPUT!J:J,$A10, INPUT!K:K, $B$3) -> 31 | F10: =SUMIFS(INPUT!G:G, INPUT!J:J,$A10, INPUT!K:K, $B$3) -> 1228.8
A11: TONY | B11: =COUNTIFS(INPUT!J:J,$A11, INPUT!K:K, $B$3) -> 43 | C11: =SUMIFS(INPUT!C:C, INPUT!J:J,$A11, INPUT!K:K, $B$3) -> 2967 | D11: =SUMIFS(INPUT!E:E, INPUT!J:J,$A11, INPUT!K:K, $B$3) -> 1780.2 | E11: =SUMIFS(INPUT!D:D, INPUT!J:J,$A11, INPUT!K:K, $B$3) -> 38 | F11: =SUMIFS(INPUT!G:G, INPUT!J:J,$A11, INPUT!K:K, $B$3) -> 1186.8
A12: STEVEN | B12: =COUNTIFS(INPUT!J:J,$A12, INPUT!K:K, $B$3) -> 0 | C12: =SUMIFS(INPUT!C:C, INPUT!J:J,$A12, INPUT!K:K, $B$3) -> 0 | D12: =SUMIFS(INPUT!E:E, INPUT!J:J,$A12, INPUT!K:K, $B$3) -> 0 | E12: =SUMIFS(INPUT!D:D, INPUT!J:J,$A12, INPUT!K:K, $B$3) -> 0 | F12: =SUMIFS(INPUT!G:G, INPUT!J:J,$A12, INPUT!K:K, $B$3) -> 0
A13: BEN | B13: =COUNTIFS(INPUT!J:J,$A13, INPUT!K:K, $B$3) -> 0 | C13: =SUMIFS(INPUT!C:C, INPUT!J:J,$A13, INPUT!K:K, $B$3) -> 0 | D13: =SUMIFS(INPUT!E:E, INPUT!J:J,$A13, INPUT!K:K, $B$3) -> 0 | E13: =SUMIFS(INPUT!D:D, INPUT!J:J,$A13, INPUT!K:K, $B$3) -> 0 | F13: =SUMIFS(INPUT!G:G, INPUT!J:J,$A13, INPUT!K:K, $B$3) -> 0
A15: CHI TIẾT THEO NGÀY (trong tuần) - theo Selected Tech
A16: Date | B16: # Khách | C16: Service | D16: Tip | E16: Tech Share | F16: Salon Gross | G16: Salon Net
A17: =INT($B$3)+0 -> 46055 | B17: =IF($E$3="ALL",COUNTIFS(INPUT!K:K,$B$3,INPUT!L:L,A17),COUNTIFS(INPUT!J:J,$E$3, INPUT!K:K,$B$3, INPUT!L:L, A17)) -> 5 | C17: =IF($E$3="ALL",SUMIFS(INPUT!C:C,INPUT!K:K,$B$3,INPUT!L:L,A17),SUMIFS(INPUT!C:C, INPUT!J:J,$E$3, INPUT!K:K,$B$3, INPUT!L:L, A17)) -> 328 | D17: =IF($E$3="ALL",SUMIFS(INPUT!D:D,INPUT!K:K,$B$3,INPUT!L:L,A17),SUMIFS(INPUT!D:D, INPUT!J:J,$E$3, INPUT!K:K,$B$3, INPUT!L:L, A17)) -> 7 | E17: =IF($E$3="ALL",SUMIFS(INPUT!E:E,INPUT!K:K,$B$3,INPUT!L:L,A17),SUMIFS(INPUT!E:E, INPUT!J:J,$E$3, INPUT!K:K,$B$3, INPUT!L:L, A17)) -> 196.8 | F17: =IF($E$3="ALL",SUMIFS(INPUT!F:F,INPUT!K:K,$B$3,INPUT!L:L,A17),SUMIFS(INPUT!F:F, INPUT!J:J,$E$3, INPUT!K:K,$B$3, INPUT!L:L, A17)) -> 131.2 | G17: =IF($E$3="ALL",SUMIFS(INPUT!G:G,INPUT!K:K,$B$3,INPUT!L:L,A17),SUMIFS(INPUT!G:G, INPUT!J:J,$E$3, INPUT!K:K,$B$3, INPUT!L:L, A17)) -> 131.2
A18: =INT($B$3)+1 -> 46056 | B18: =IF($E$3="ALL",COUNTIFS(INPUT!K:K,$B$3,INPUT!L:L,A18),COUNTIFS(INPUT!J:J,$E$3, INPUT!K:K,$B$3, INPUT!L:L, A18)) -> 5 | C18: =IF($E$3="ALL",SUMIFS(INPUT!C:C,INPUT!K:K,$B$3,INPUT!L:L,A18),SUMIFS(INPUT!C:C, INPUT!J:J,$E$3, INPUT!K:K,$B$3, INPUT!L:L, A18)) -> 310 | D18: =IF($E$3="ALL",SUMIFS(INPUT!D:D,INPUT!K:K,$B$3,INPUT!L:L,A18),SUMIFS(INPUT!D:D, INPUT!J:J,$E$3, INPUT!K:K,$B$3, INPUT!L:L, A18)) -> 11 | E18: =IF($E$3="ALL",SUMIFS(INPUT!E:E,INPUT!K:K,$B$3,INPUT!L:L,A18),SUMIFS(INPUT!E:E, INPUT!J:J,$E$3, INPUT!K:K,$B$3, INPUT!L:L, A18)) -> 186 | F18: =IF($E$3="ALL",SUMIFS(INPUT!F:F,INPUT!K:K,$B$3,INPUT!L:L,A18),SUMIFS(INPUT!F:F, INPUT!J:J,$E$3, INPUT!K:K,$B$3, INPUT!L:L, A18)) -> 124 | G18: =IF($E$3="ALL",SUMIFS(INPUT!G:G,INPUT!K:K,$B$3,INPUT!L:L,A18),SUMIFS(INPUT!G:G, INPUT!J:J,$E$3, INPUT!K:K,$B$3, INPUT!L:L, A18)) -> 124
A19: =INT($B$3)+2 -> 46057 | B19: =IF($E$3="ALL",COUNTIFS(INPUT!K:K,$B$3,INPUT!L:L,A19),COUNTIFS(INPUT!J:J,$E$3, INPUT!K:K,$B$3, INPUT!L:L, A19)) -> 9 | C19: =IF($E$3="ALL",SUMIFS(INPUT!C:C,INPUT!K:K,$B$3,INPUT!L:L,A19),SUMIFS(INPUT!C:C, INPUT!J:J,$E$3, INPUT!K:K,$B$3, INPUT!L:L, A19)) -> 601 | D19: =IF($E$3="ALL",SUMIFS(INPUT!D:D,INPUT!K:K,$B$3,INPUT!L:L,A19),SUMIFS(INPUT!D:D, INPUT!J:J,$E$3, INPUT!K:K,$B$3, INPUT!L:L, A19)) -> 45 | E19: =IF($E$3="ALL",SUMIFS(INPUT!E:E,INPUT!K:K,$B$3,INPUT!L:L,A19),SUMIFS(INPUT!E:E, INPUT!J:J,$E$3, INPUT!K:K,$B$3, INPUT!L:L, A19)) -> 360.6 | F19: =IF($E$3="ALL",SUMIFS(INPUT!F:F,INPUT!K:K,$B$3,INPUT!L:L,A19),SUMIFS(INPUT!F:F, INPUT!J:J,$E$3, INPUT!K:K,$B$3, INPUT!L:L, A19)) -> 240.4 | G19: =IF($E$3="ALL",SUMIFS(INPUT!G:G,INPUT!K:K,$B$3,INPUT!L:L,A19),SUMIFS(INPUT!G:G, INPUT!J:J,$E$3, INPUT!K:K,$B$3, INPUT!L:L, A19)) -> 240.4
A20: =INT($B$3)+3 -> 46058 | B20: =IF($E$3="ALL",COUNTIFS(INPUT!K:K,$B$3,INPUT!L:L,A20),COUNTIFS(INPUT!J:J,$E$3, INPUT!K:K,$B$3, INPUT!L:L, A20)) -> 5 | C20: =IF($E$3="ALL",SUMIFS(INPUT!C:C,INPUT!K:K,$B$3,INPUT!L:L,A20),SUMIFS(INPUT!C:C, INPUT!J:J,$E$3, INPUT!K:K,$B$3, INPUT!L:L, A20)) -> 443 | D20: =IF($E$3="ALL",SUMIFS(INPUT!D:D,INPUT!K:K,$B$3,INPUT!L:L,A20),SUMIFS(INPUT!D:D, INPUT!J:J,$E$3, INPUT!K:K,$B$3, INPUT!L:L, A20)) -> 0 | E20: =IF($E$3="ALL",SUMIFS(INPUT!E:E,INPUT!K:K,$B$3,INPUT!L:L,A20),SUMIFS(INPUT!E:E, INPUT!J:J,$E$3, INPUT!K:K,$B$3, INPUT!L:L, A20)) -> 265.8 | F20: =IF($E$3="ALL",SUMIFS(INPUT!F:F,INPUT!K:K,$B$3,INPUT!L:L,A20),SUMIFS(INPUT!F:F, INPUT!J:J,$E$3, INPUT!K:K,$B$3, INPUT!L:L, A20)) -> 177.2 | G20: =IF($E$3="ALL",SUMIFS(INPUT!G:G,INPUT!K:K,$B$3,INPUT!L:L,A20),SUMIFS(INPUT!G:G, INPUT!J:J,$E$3, INPUT!K:K,$B$3, INPUT!L:L, A20)) -> 177.2
A21: =INT($B$3)+4 -> 46059 | B21: =IF($E$3="ALL",COUNTIFS(INPUT!K:K,$B$3,INPUT!L:L,A21),COUNTIFS(INPUT!J:J,$E$3, INPUT!K:K,$B$3, INPUT!L:L, A21)) -> 9 | C21: =IF($E$3="ALL",SUMIFS(INPUT!C:C,INPUT!K:K,$B$3,INPUT!L:L,A21),SUMIFS(INPUT!C:C, INPUT!J:J,$E$3, INPUT!K:K,$B$3, INPUT!L:L, A21)) -> 601 | D21: =IF($E$3="ALL",SUMIFS(INPUT!D:D,INPUT!K:K,$B$3,INPUT!L:L,A21),SUMIFS(INPUT!D:D, INPUT!J:J,$E$3, INPUT!K:K,$B$3, INPUT!L:L, A21)) -> 0 | E21: =IF($E$3="ALL",SUMIFS(INPUT!E:E,INPUT!K:K,$B$3,INPUT!L:L,A21),SUMIFS(INPUT!E:E, INPUT!J:J,$E$3, INPUT!K:K,$B$3, INPUT!L:L, A21)) -> 360.6 | F21: =IF($E$3="ALL",SUMIFS(INPUT!F:F,INPUT!K:K,$B$3,INPUT!L:L,A21),SUMIFS(INPUT!F:F, INPUT!J:J,$E$3, INPUT!K:K,$B$3, INPUT!L:L, A21)) -> 240.4 | G21: =IF($E$3="ALL",SUMIFS(INPUT!G:G,INPUT!K:K,$B$3,INPUT!L:L,A21),SUMIFS(INPUT!G:G, INPUT!J:J,$E$3, INPUT!K:K,$B$3, INPUT!L:L, A21)) -> 240.4
A22: =INT($B$3)+5 -> 46060 | B22: =IF($E$3="ALL",COUNTIFS(INPUT!K:K,$B$3,INPUT!L:L,A22),COUNTIFS(INPUT!J:J,$E$3, INPUT!K:K,$B$3, INPUT!L:L, A22)) -> 7 | C22: =IF($E$3="ALL",SUMIFS(INPUT!C:C,INPUT!K:K,$B$3,INPUT!L:L,A22),SUMIFS(INPUT!C:C, INPUT!J:J,$E$3, INPUT!K:K,$B$3, INPUT!L:L, A22)) -> 471 | D22: =IF($E$3="ALL",SUMIFS(INPUT!D:D,INPUT!K:K,$B$3,INPUT!L:L,A22),SUMIFS(INPUT!D:D, INPUT!J:J,$E$3, INPUT!K:K,$B$3, INPUT!L:L, A22)) -> 0 | E22: =IF($E$3="ALL",SUMIFS(INPUT!E:E,INPUT!K:K,$B$3,INPUT!L:L,A22),SUMIFS(INPUT!E:E, INPUT!J:J,$E$3, INPUT!K:K,$B$3, INPUT!L:L, A22)) -> 282.6 | F22: =IF($E$3="ALL",SUMIFS(INPUT!F:F,INPUT!K:K,$B$3,INPUT!L:L,A22),SUMIFS(INPUT!F:F, INPUT!J:J,$E$3, INPUT!K:K,$B$3, INPUT!L:L, A22)) -> 188.4 | G22: =IF($E$3="ALL",SUMIFS(INPUT!G:G,INPUT!K:K,$B$3,INPUT!L:L,A22),SUMIFS(INPUT!G:G, INPUT!J:J,$E$3, INPUT!K:K,$B$3, INPUT!L:L, A22)) -> 188.4
A23: =INT($B$3)+6 -> 46061 | B23: =IF($E$3="ALL",COUNTIFS(INPUT!K:K,$B$3,INPUT!L:L,A23),COUNTIFS(INPUT!J:J,$E$3, INPUT!K:K,$B$3, INPUT!L:L, A23)) -> 4 | C23: =IF($E$3="ALL",SUMIFS(INPUT!C:C,INPUT!K:K,$B$3,INPUT!L:L,A23),SUMIFS(INPUT!C:C, INPUT!J:J,$E$3, INPUT!K:K,$B$3, INPUT!L:L, A23)) -> 324 | D23: =IF($E$3="ALL",SUMIFS(INPUT!D:D,INPUT!K:K,$B$3,INPUT!L:L,A23),SUMIFS(INPUT!D:D, INPUT!J:J,$E$3, INPUT!K:K,$B$3, INPUT!L:L, A23)) -> 0 | E23: =IF($E$3="ALL",SUMIFS(INPUT!E:E,INPUT!K:K,$B$3,INPUT!L:L,A23),SUMIFS(INPUT!E:E, INPUT!J:J,$E$3, INPUT!K:K,$B$3, INPUT!L:L, A23)) -> 194.4 | F23: =IF($E$3="ALL",SUMIFS(INPUT!F:F,INPUT!K:K,$B$3,INPUT!L:L,A23),SUMIFS(INPUT!F:F, INPUT!J:J,$E$3, INPUT!K:K,$B$3, INPUT!L:L, A23)) -> 129.6 | G23: =IF($E$3="ALL",SUMIFS(INPUT!G:G,INPUT!K:K,$B$3,INPUT!L:L,A23),SUMIFS(INPUT!G:G, INPUT!J:J,$E$3, INPUT!K:K,$B$3, INPUT!L:L, A23)) -> 129.6
A24: TOTAL (Tuần) | B24: =SUM(B17:B23) -> 44 | C24: =SUM(C17:C23) -> 3078 | D24: =SUM(D17:D23) -> 63 | E24: =SUM(E17:E23) -> 1846.8 | F24: =SUM(F17:F23) -> 1231.2 | G24: =SUM(G17:G23) -> 1231.2

Sheet MONTHLY_SUMMARY
A1: MONTHLY_SUMMARY (Chưa chia) - Tổng Service theo tháng
A3: Month (yyyy-mm): | B3: 2026-02 | D3: Selected Tech: | E3: ryan
A5: Tech | B5: # Khách | C5: Service (Chưa chia) | D5: Tip | E5: Tech Share (Đã chia) | F5: Salon Gross (Đã chia) | G5: Salon Net (sau discount/gift)
A6: KEN | B6: =COUNTIFS(INPUT!J:J,$A6,INPUT!A:A,">="&DATE(LEFT($B$3,4),RIGHT($B$3,2),1),INPUT!A:A,"<"&EOMONTH(DATE(LEFT($B$3,4),RIGHT($B$3,2),1),0)+1) -> 26 | C6: =SUMIFS(INPUT!C:C,INPUT!J:J,$A6,INPUT!A:A,">="&DATE(LEFT($B$3,4),RIGHT($B$3,2),1),INPUT!A:A,"<"&EOMONTH(DATE(LEFT($B$3,4),RIGHT($B$3,2),1),0)+1) -> 1835 | D6: =SUMIFS(INPUT!D:D,INPUT!J:J,$A6,INPUT!A:A,">="&DATE(LEFT($B$3,4),RIGHT($B$3,2),1),INPUT!A:A,"<"&EOMONTH(DATE(LEFT($B$3,4),RIGHT($B$3,2),1),0)+1) -> 0 | E6: =SUMIFS(INPUT!E:E,INPUT!J:J,$A6,INPUT!A:A,">="&DATE(LEFT($B$3,4),RIGHT($B$3,2),1),INPUT!A:A,"<"&EOMONTH(DATE(LEFT($B$3,4),RIGHT($B$3,2),1),0)+1) -> 0 | F6: =SUMIFS(INPUT!F:F,INPUT!J:J,$A6,INPUT!A:A,">="&DATE(LEFT($B$3,4),RIGHT($B$3,2),1),INPUT!A:A,"<"&EOMONTH(DATE(LEFT($B$3,4),RIGHT($B$3,2),1),0)+1) -> 1835 | G6: =SUMIFS(INPUT!G:G,INPUT!J:J,$A6,INPUT!A:A,">="&DATE(LEFT($B$3,4),RIGHT($B$3,2),1),INPUT!A:A,"<"&EOMONTH(DATE(LEFT($B$3,4),RIGHT($B$3,2),1),0)+1) -> 1835
